Workbook
Name analysis_period: Inputs!$C$36
Name annual_fuel_usage: Inputs!$C$23
Name AnnualLandLease: Inputs!$D$213
Name AnnualOMCapacity: Inputs!$D$166
Name AnnualOMFixed: Inputs!$D$165
Name AnnualOMProduction: Inputs!$D$167
Name AnnualPBIFederal: Inputs!$D$172
Name AnnualPBIOther: Inputs!$D$175
Name AnnualPBIState: Inputs!$D$173
Name AnnualPBIUtility: Inputs!$D$174
Name AnnualPTCFederal: Inputs!$D$184
Name AnnualPTCState: Inputs!$D$185
Name AnnualTaxFederal: Inputs!$C$170
Name AnnualTaxState: Inputs!$C$169
Name batt_annual_discharge_energy: Inputs!$C$153
Name cbi_fed_amount: Inputs!$C$125
Name cbi_fed_deprbas_fed: Inputs!$G$125
Name cbi_fed_deprbas_sta: Inputs!$H$125
Name cbi_fed_maxvalue: Inputs!$D$125
Name cbi_fed_tax_fed: Inputs!$E$125
Name cbi_fed_tax_sta: Inputs!$F$125
Name cbi_oth_amount: Inputs!$C$128
Name cbi_oth_deprbas_fed: Inputs!$G$128
Name cbi_oth_deprbas_sta: Inputs!$H$128
Name cbi_oth_maxvalue: Inputs!$D$128
Name cbi_oth_tax_fed: Inputs!$E$128
Name cbi_oth_tax_sta: Inputs!$F$128
Name cbi_sta_amount: Inputs!$C$126
Name cbi_sta_deprbas_fed: Inputs!$G$126
Name cbi_sta_deprbas_sta: Inputs!$H$126
Name cbi_sta_maxvalue: Inputs!$D$126
Name cbi_sta_tax_fed: Inputs!$E$126
Name cbi_sta_tax_sta: Inputs!$F$126
Name cbi_uti_amount: Inputs!$C$127
Name cbi_uti_deprbas_fed: Inputs!$G$127
Name cbi_uti_deprbas_sta: Inputs!$H$127
Name cbi_uti_maxvalue: Inputs!$D$127
Name cbi_uti_tax_fed: Inputs!$E$127
Name cbi_uti_tax_sta: Inputs!$F$127
Name cf_annual_cost_lcos: Inputs!$C$210
Name cf_annual_discharge_lcos: Inputs!$C$211
Name cf_battery_replacement_cost: Inputs!$C$190
Name cf_capacity_payment: Inputs!$C$158
Name cf_curtailment_value: Inputs!$C$159
Name cf_disbursement_debtservice: Inputs!$C$205
Name cf_energy_net: Inputs!$C$151
Name cf_energy_purchases: Inputs!$C$150
Name cf_energy_sales: Inputs!$C$149
Name cf_energy_value: Inputs!$C$157
Name cf_energy_without_battery: Inputs!$C$152
Name cf_fuelcell_replacement_cost: Inputs!$C$195
Name cf_funding_debtservice: Inputs!$C$204
Name cf_om_capacity1_expense: Inputs!$C$188
Name cf_om_capacity2_expense: Inputs!$C$193
Name cf_om_fixed1_expense: Inputs!$C$187
Name cf_om_fixed2_expense: Inputs!$C$192
Name cf_om_fuel_expense: Inputs!$C$198
Name cf_om_opt_fuel_1_expense: Inputs!$C$199
Name cf_om_opt_fuel_2_expense: Inputs!$C$200
Name cf_om_production1_expense: Inputs!$C$189

Sheet Inputs
B1: Third Party Ownership - Host/Developer Inputs
B2: SYSTEM DESIGN | E2: KEY
B3: Nameplate capacity (kW) | C3: 0 | E3: Calculated
E4: Input from SAM
B5: SYSTEM COSTS | E5: Annual value from SAM
B6: Total installed cost ($) | C6: 0 | E6: Value depends on option in SAM
B8: OPERATION AND MAINTENANCE COSTS | E8: METRICS
B9: Fixed annual cost ($/yr) | C9: 0 | E9: PPA price, year 1 (¢/kWh) | F9: ='Cash Flow'!C28 -> 0
B10: Escalation (% above inflation) | C10: 0 | E10: PPA price escalation (%/yr) | F10: =ppa_escalation -> 0
B11: Fixed cost by capacity ($/kW-yr) | C11: 0 | E11: Levelized PPA price nominal (¢/kWh) | F11: ='Cash Flow'!B164 -> 0
B12: Escalation (% above inflation) | C12: 0 | E12: LCOE, nominal (¢/kWh) | F12: ='Cash Flow'!B160 -> 0
B13: Variable cost by generation ($/MWh) | C13: 0 | E13: Developer NPV ($) | F13: ='Cash Flow'!B151 -> 0
B14: Escalation (% above inflation) | C14: 0 | E14: Host NPV ($) | F14: ='Cash Flow'!B21 + NPV(host_nominal_discount_rate/100,'Cash Flow'!C21:AP21) -> 0
E15: Host indifference point, year 1 (¢/kWh) | F15: ='Cash Flow'!C16 -> 0
B16: LAND LEASE | E16: Levelized indifference point (nominal) (¢/kWh) | F16: =IF('Cash Flow'!B159<>0,NPV(host_nominal_discount_rate/100,'Cash Flow'!C15:AP15)*100/NPV(host_nominal_discount_rate/100,'Cash Flow'!C156:AP156),0) -> 0
B17: Land area estimate (acres) | C17: 0
B18: Annual land lease cost ($/acre) | C18: 0
B19: Land lease escalation rate (% above inflation) | C19: 0
B21: FUEL COSTS (CSP, GENERIC, AND BIOPOWER SYSTEMS ONLY)
B22: Fuel (CSP and generic system only)
B23: Annual usage (kWh) | C23: 0
B24: Heat rate (MMBtu/MWh) | C24: 0
B25: Cost ($/MMBtu) | C25: 0
B26: Escalation (%/year above inflation) | C26: 0
B28: FINANCIAL PARAMETERS
B29: Solution Mode
B30: IRR Target | C30: Calculated
B31: Target year | C31: Calculated
B32: PPA price ($/kWh) | C32: 0
B33: PPA price escalation (%/year) | C33: 0
B34: PPA price is modified by TOD multipliers | C34: No
B35: Analysis Parameters
B36: Analysis period (years, 40 max) | C36: 0
B37: Inflation rate (%/year) | C37: 0
B38: Host real discount rate (%/year) | C38: 0
B39: Host nominal discount rate (%/year) | C39: =((inflation_rate/100+1)*(host_real_discount_rate/100+1)-1)*100 -> 0
B40: Project (developer) real discount rate (%/year) | C40: 0
B41: Project (developer) nominal discount rate (%/year) | C41: =((inflation_rate/100+1)*(real_discount_rate/100+1)-1)*100 -> 0
B42: Tax and Insurance Rates
B43: Federal income tax rate in Year 1 (%/year) | C43: =AnnualTaxFederal -> 0
...

Sheet Cash Flow
A1: Third Party Ownership - Host/Developer Cash Flow
A2: Operating Year | B2: 0 | C2: =IF(B2<analysis_period,B2+1,"") | D2: =IF(C2<analysis_period,C2+1,"") | E2: =IF(D2<analysis_period,D2+1,"") | F2: =IF(E2<analysis_period,E2+1,"") | G2: =IF(F2<analysis_period,F2+1,"") | H2: =IF(G2<analysis_period,G2+1,"") | I2: =IF(H2<analysis_period,H2+1,"") | J2: =IF(I2<analysis_period,I2+1,"") | ... AP2: =IF(AO2<analysis_period,AO2+1,"")
A4: Energy
A5: Electricity to grid (AC kWh) | B5: {=Inputs!C149:AQ150} -> 0 | C5: 0 | D5: 0 | E5: 0 | F5: 0 | G5: 0 | H5: 0 | I5: 0 | J5: 0 | K5: 0 | L5: 0 | M5: 0 | N5: 0 | O5: 0 | P5: 0 | Q5: 0 | R5: 0 | S5: 0 | T5: 0 | U5: 0 | V5: 0 | W5: 0 | X5: 0 | Y5: 0 | Z5: 0 | AA5: 0 | AB5: 0 | AC5: 0 | AD5: 0 | AE5: 0 | AF5: 0 | AG5: 0 | AH5: 0 | AI5: 0 | AJ5: 0 | AK5: 0 | AL5: 0 | AM5: 0 | AN5: 0 | AO5: 0 | AP5: 0
A6: Electricity from grid (AC kWh) | B6: 0 | C6: 0 | D6: 0 | E6: 0 | F6: 0 | G6: 0 | H6: 0 | I6: 0 | J6: 0 | K6: 0 | L6: 0 | M6: 0 | N6: 0 | O6: 0 | P6: 0 | Q6: 0 | R6: 0 | S6: 0 | T6: 0 | U6: 0 | V6: 0 | W6: 0 | X6: 0 | Y6: 0 | Z6: 0 | AA6: 0 | AB6: 0 | AC6: 0 | AD6: 0 | AE6: 0 | AF6: 0 | AG6: 0 | AH6: 0 | AI6: 0 | AJ6: 0 | AK6: 0 | AL6: 0 | AM6: 0 | AN6: 0 | AO6: 0 | AP6: 0
A7: Electricity to grid net (AC kWh) | B7: =SUM(B5:B6) -> 0 | C7: =SUM(C5:C6) -> 0 | D7: =SUM(D5:D6) -> 0 | E7: =SUM(E5:E6) -> 0 | F7: =SUM(F5:F6) -> 0 | G7: =SUM(G5:G6) -> 0 | H7: =SUM(H5:H6) -> 0 | I7: =SUM(I5:I6) -> 0 | ... AP7: =SUM(AP5:AP6) -> 0
A8: Electricity generated without storage (AC kWh) | B8: {=Inputs!C152:AQ154} -> 0 | C8: 0 | D8: 0 | E8: 0 | F8: 0 | G8: 0 | H8: 0 | I8: 0 | J8: 0 | K8: 0 | L8: 0 | M8: 0 | N8: 0 | O8: 0 | P8: 0 | Q8: 0 | R8: 0 | S8: 0 | T8: 0 | U8: 0 | V8: 0 | W8: 0 | X8: 0 | Y8: 0 | Z8: 0 | AA8: 0 | AB8: 0 | AC8: 0 | AD8: 0 | AE8: 0 | AF8: 0 | AG8: 0 | AH8: 0 | AI8: 0 | AJ8: 0 | AK8: 0 | AL8: 0 | AM8: 0 | AN8: 0 | AO8: 0 | AP8: 0
A9: Battery annual energy discharged (AC kWh) | B9: 0 | C9: 0 | D9: 0 | E9: 0 | F9: 0 | G9: 0 | H9: 0 | I9: 0 | J9: 0 | K9: 0 | L9: 0 | M9: 0 | N9: 0 | O9: 0 | P9: 0 | Q9: 0 | R9: 0 | S9: 0 | T9: 0 | U9: 0 | V9: 0 | W9: 0 | X9: 0 | Y9: 0 | Z9: 0 | AA9: 0 | AB9: 0 | AC9: 0 | AD9: 0 | AE9: 0 | AF9: 0 | AG9: 0 | AH9: 0 | AI9: 0 | AJ9: 0 | AK9: 0 | AL9: 0 | AM9: 0 | AN9: 0 | AO9: 0 | AP9: 0
A10: Fuel cell annual energy discharged (AC kWh) | B10: 0 | C10: 0 | D10: 0 | E10: 0 | F10: 0 | G10: 0 | H10: 0 | I10: 0 | J10: 0 | K10: 0 | L10: 0 | M10: 0 | N10: 0 | O10: 0 | P10: 0 | Q10: 0 | R10: 0 | S10: 0 | T10: 0 | U10: 0 | V10: 0 | W10: 0 | X10: 0 | Y10: 0 | Z10: 0 | AA10: 0 | AB10: 0 | AC10: 0 | AD10: 0 | AE10: 0 | AF10: 0 | AG10: 0 | AH10: 0 | AI10: 0 | AJ10: 0 | AK10: 0 | AL10: 0 | AM10: 0 | AN10: 0 | AO10: 0 | AP10: 0
A12: Host Costs and Savings
A13: Electricity bill without system | B13: {=Inputs!C163:AQ163} -> 0 | C13: 0 | D13: 0 | E13: 0 | F13: 0 | G13: 0 | H13: 0 | I13: 0 | J13: 0 | K13: 0 | L13: 0 | M13: 0 | N13: 0 | O13: 0 | P13: 0 | Q13: 0 | R13: 0 | S13: 0 | T13: 0 | U13: 0 | V13: 0 | W13: 0 | X13: 0 | Y13: 0 | Z13: 0 | AA13: 0 | AB13: 0 | AC13: 0 | AD13: 0 | AE13: 0 | AF13: 0 | AG13: 0 | AH13: 0 | AI13: 0 | AJ13: 0 | AK13: 0 | AL13: 0 | AM13: 0 | AN13: 0 | AO13: 0 | AP13: 0
A14: Electricity bill with system | B14: {=Inputs!C162:AQ162} -> 0 | C14: 0 | D14: 0 | E14: 0 | F14: 0 | G14: 0 | H14: 0 | I14: 0 | J14: 0 | K14: 0 | L14: 0 | M14: 0 | N14: 0 | O14: 0 | P14: 0 | Q14: 0 | R14: 0 | S14: 0 | T14: 0 | U14: 0 | V14: 0 | W14: 0 | X14: 0 | Y14: 0 | Z14: 0 | AA14: 0 | AB14: 0 | AC14: 0 | AD14: 0 | AE14: 0 | AF14: 0 | AG14: 0 | AH14: 0 | AI14: 0 | AJ14: 0 | AK14: 0 | AL14: 0 | AM14: 0 | AN14: 0 | AO14: 0 | AP14: 0
A15: Savings | B15: =B13-B14 -> 0 | C15: =C13-C14 -> 0 | D15: =D13-D14 -> 0 | E15: =E13-E14 -> 0 | F15: =F13-F14 -> 0 | G15: =G13-G14 -> 0 | H15: =H13-H14 -> 0 | I15: =I13-I14 -> 0 | ... AP15: =AP13-AP14 -> 0
A16: Indifference point (¢/kWh) | B16: =IF(B$5=0,0,B$15*100/B$5) -> 0 | C16: =IF(C$5=0,0,C$15*100/C$5) -> 0 | D16: =IF(D$5=0,0,D$15*100/D$5) -> 0 | E16: =IF(E$5=0,0,E$15*100/E$5) -> 0 | F16: =IF(F$5=0,0,F$15*100/F$5) -> 0 | G16: =IF(G$5=0,0,G$15*100/G$5) -> 0 | H16: =IF(H$5=0,0,H$15*100/H$5) -> 0 | I16: =IF(I$5=0,0,I$15*100/I$5) -> 0 | ... AP16: =IF(AP$5=0,0,AP$15*100/AP$5) -> 0
A17: Agreement cost
A18: Electricity to grid net (AC kWh) | B18: =B$5 -> 0 | C18: =C$5 -> 0 | D18: =D$5 -> 0 | E18: =E$5 -> 0 | F18: =F$5 -> 0 | G18: =G$5 -> 0 | H18: =H$5 -> 0 | I18: =I$5 -> 0 | ... AP18: =AP$5 -> 0
A19: PPA price (¢/kWh) | B19: {=Inputs!C156:AQ156} -> 0 | C19: 0 | D19: 0 | E19: 0 | F19: 0 | G19: 0 | H19: 0 | I19: 0 | J19: 0 | K19: 0 | L19: 0 | M19: 0 | N19: 0 | O19: 0 | P19: 0 | Q19: 0 | R19: 0 | S19: 0 | T19: 0 | U19: 0 | V19: 0 | W19: 0 | X19: 0 | Y19: 0 | Z19: 0 | AA19: 0 | AB19: 0 | AC19: 0 | AD19: 0 | AE19: 0 | AF19: 0 | AG19: 0 | AH19: 0 | AI19: 0 | AJ19: 0 | AK19: 0 | AL19: 0 | AM19: 0 | AN19: 0 | AO19: 0 | AP19: 0
A20: Total agreement cost | B20: =B$19*B$18/100 -> 0 | C20: =C$19*C$18/100 -> 0 | D20: =D$19*D$18/100 -> 0 | E20: =E$19*E$18/100 -> 0 | F20: =F$19*F$18/100 -> 0 | G20: =G$19*G$18/100 -> 0 | H20: =H$19*H$18/100 -> 0 | I20: =I$19*I$18/100 -> 0 | ... AP20: =AP$19*AP$18/100 -> 0
A21: After-tax cash flow | B21: =B$15-B$20 -> 0 | C21: =C$15-C$20 -> 0 | D21: =D$15-D$20 -> 0 | E21: =E$15-E$20 -> 0 | F21: =F$15-F$20 -> 0 | G21: =G$15-G$20 -> 0 | H21: =H$15-H$20 -> 0 | I21: =I$15-I$20 -> 0 | ... AP21: =AP$15-AP$20 -> 0
A22: Payback | B22: =B$21 -> 0 | C22: =C$21 -> 0 | D22: =D$21 -> 0 | E22: =E$21 -> 0 | F22: =F$21 -> 0 | G22: =G$21 -> 0 | H22: =H$21 -> 0 | I22: =I$21 -> 0 | ... AP22: =AP$21 -> 0
A23: Cumulative payback | B23: 0 | C23: =B$23+C$22 -> 0 | D23: =C$23+D$22 -> 0 | E23: =D$23+E$22 -> 0 | F23: =E$23+F$22 -> 0 | G23: =F$23+G$22 -> 0 | H23: =G$23+H$22 -> 0 | I23: =H$23+I$22 -> 0 | J23: =I$23+J$22 -> 0 | ... AP23: =AO$23+AP$22 -> 0
A25: Developer Revenues and Costs
A26: PPA revenue
A27: Electricity to grid (AC kWh) | C27: =C$5 -> 0 | D27: =D$5 -> 0 | E27: =E$5 -> 0 | F27: =F$5 -> 0 | G27: =G$5 -> 0 | H27: =H$5 -> 0 | I27: =I$5 -> 0 | J27: =J$5 -> 0 | ... AP27: =AP$5 -> 0
A28: Price (¢/kWh) | B28: {=Inputs!C156:AQ156} -> 0 | C28: 0 | D28: 0 | E28: 0 | F28: 0 | G28: 0 | H28: 0 | I28: 0 | J28: 0 | K28: 0 | L28: 0 | M28: 0 | N28: 0 | O28: 0 | P28: 0 | Q28: 0 | R28: 0 | S28: 0 | T28: 0 | U28: 0 | V28: 0 | W28: 0 | X28: 0 | Y28: 0 | Z28: 0 | AA28: 0 | AB28: 0 | AC28: 0 | AD28: 0 | AE28: 0 | AF28: 0 | AG28: 0 | AH28: 0 | AI28: 0 | AJ28: 0 | AK28: 0 | AL28: 0 | AM28: 0 | AN28: 0 | AO28: 0 | AP28: 0
A29: PPA revenue (TOD price multipliers may apply) | B29: {=Inputs!C157:AQ157} -> 0 | C29: 0 | D29: 0 | E29: 0 | F29: 0 | G29: 0 | H29: 0 | I29: 0 | J29: 0 | K29: 0 | L29: 0 | M29: 0 | N29: 0 | O29: 0 | P29: 0 | Q29: 0 | R29: 0 | S29: 0 | T29: 0 | U29: 0 | V29: 0 | W29: 0 | X29: 0 | Y29: 0 | Z29: 0 | AA29: 0 | AB29: 0 | AC29: 0 | AD29: 0 | AE29: 0 | AF29: 0 | AG29: 0 | AH29: 0 | AI29: 0 | AJ29: 0 | AK29: 0 | AL29: 0 | AM29: 0 | AN29: 0 | AO29: 0 | AP29: 0
A30: Other revenue
A31: Capacity payments | B31: {=Inputs!C158:AQ160} -> 0 | C31: 0 | D31: 0 | E31: 0 | F31: 0 | G31: 0 | H31: 0 | I31: 0 | J31: 0 | K31: 0 | L31: 0 | M31: 0 | N31: 0 | O31: 0 | P31: 0 | Q31: 0 | R31: 0 | S31: 0 | T31: 0 | U31: 0 | V31: 0 | W31: 0 | X31: 0 | Y31: 0 | Z31: 0 | AA31: 0 | AB31: 0 | AC31: 0 | AD31: 0 | AE31: 0 | AF31: 0 | AG31: 0 | AH31: 0 | AI31: 0 | AJ31: 0 | AK31: 0 | AL31: 0 | AM31: 0 | AN31: 0 | AO31: 0 | AP31: 0
A32: Curtailment payments | B32: 0 | C32: 0 | D32: 0 | E32: 0 | F32: 0 | G32: 0 | H32: 0 | I32: 0 | J32: 0 | K32: 0 | L32: 0 | M32: 0 | N32: 0 | O32: 0 | P32: 0 | Q32: 0 | R32: 0 | S32: 0 | T32: 0 | U32: 0 | V32: 0 | W32: 0 | X32: 0 | Y32: 0 | Z32: 0 | AA32: 0 | AB32: 0 | AC32: 0 | AD32: 0 | AE32: 0 | AF32: 0 | AG32: 0 | AH32: 0 | AI32: 0 | AJ32: 0 | AK32: 0 | AL32: 0 | AM32: 0 | AN32: 0 | AO32: 0 | AP32: 0
A33: Thermal revenue (fuel cell only) | B33: 0 | C33: 0 | D33: 0 | E33: 0 | F33: 0 | G33: 0 | H33: 0 | I33: 0 | J33: 0 | K33: 0 | L33: 0 | M33: 0 | N33: 0 | O33: 0 | P33: 0 | Q33: 0 | R33: 0 | S33: 0 | T33: 0 | U33: 0 | V33: 0 | W33: 0 | X33: 0 | Y33: 0 | Z33: 0 | AA33: 0 | AB33: 0 | AC33: 0 | AD33: 0 | AE33: 0 | AF33: 0 | AG33: 0 | AH33: 0 | AI33: 0 | AJ33: 0 | AK33: 0 | AL33: 0 | AM33: 0 | AN33: 0 | AO33: 0 | AP33: 0
A34: Production Based Incentive (included if available for debt service)
A35: Federal | C35: =IF(pbi_fed_for_ds="Yes",C590,0) -> 0 | D35: =IF(pbi_fed_for_ds="Yes",D590,0) -> 0 | E35: =IF(pbi_fed_for_ds="Yes",E590,0) -> 0 | F35: =IF(pbi_fed_for_ds="Yes",F590,0) -> 0 | G35: =IF(pbi_fed_for_ds="Yes",G590,0) -> 0 | H35: =IF(pbi_fed_for_ds="Yes",H590,0) -> 0 | I35: =IF(pbi_fed_for_ds="Yes",I590,0) -> 0 | J35: =IF(pbi_fed_for_ds="Yes",J590,0) -> 0 | ... AP35: =IF(pbi_fed_for_ds="Yes",AP590,0) -> 0
A36: State | C36: =IF(pbi_sta_for_ds="Yes",C594,0) -> 0 | D36: =IF(pbi_sta_for_ds="Yes",D594,0) -> 0 | E36: =IF(pbi_sta_for_ds="Yes",E594,0) -> 0 | F36: =IF(pbi_sta_for_ds="Yes",F594,0) -> 0 | G36: =IF(pbi_sta_for_ds="Yes",G594,0) -> 0 | H36: =IF(pbi_sta_for_ds="Yes",H594,0) -> 0 | I36: =IF(pbi_sta_for_ds="Yes",I594,0) -> 0 | J36: =IF(pbi_sta_for_ds="Yes",J594,0) -> 0 | ... AP36: =IF(pbi_sta_for_ds="Yes",AP594,0) -> 0
A37: Utility | C37: =IF(pbi_uti_for_ds="Yes",C598,0) -> 0 | D37: =IF(pbi_uti_for_ds="Yes",D598,0) -> 0 | E37: =IF(pbi_uti_for_ds="Yes",E598,0) -> 0 | F37: =IF(pbi_uti_for_ds="Yes",F598,0) -> 0 | G37: =IF(pbi_uti_for_ds="Yes",G598,0) -> 0 | H37: =IF(pbi_uti_for_ds="Yes",H598,0) -> 0 | I37: =IF(pbi_uti_for_ds="Yes",I598,0) -> 0 | J37: =IF(pbi_uti_for_ds="Yes",J598,0) -> 0 | ... AP37: =IF(pbi_uti_for_ds="Yes",AP598,0) -> 0
A38: Other | C38: =IF(pbi_oth_for_ds="Yes",C602,0) -> 0 | D38: =IF(pbi_oth_for_ds="Yes",D602,0) -> 0 | E38: =IF(pbi_oth_for_ds="Yes",E602,0) -> 0 | F38: =IF(pbi_oth_for_ds="Yes",F602,0) -> 0 | G38: =IF(pbi_oth_for_ds="Yes",G602,0) -> 0 | H38: =IF(pbi_oth_for_ds="Yes",H602,0) -> 0 | I38: =IF(pbi_oth_for_ds="Yes",I602,0) -> 0 | J38: =IF(pbi_oth_for_ds="Yes",J602,0) -> 0 | ... AP38: =IF(pbi_oth_for_ds="Yes",AP602,0) -> 0
A39: Total PBI | C39: =SUM(C35:C38) -> 0 | D39: =SUM(D35:D38) -> 0 | E39: =SUM(E35:E38) -> 0 | F39: =SUM(F35:F38) -> 0 | G39: =SUM(G35:G38) -> 0 | H39: =SUM(H35:H38) -> 0 | I39: =SUM(I35:I38) -> 0 | J39: =SUM(J35:J38) -> 0 | ... AP39: =SUM(AP35:AP38) -> 0
A40: Salvage Value | C40: =IF(C2=analysis_period,total_installed_cost*salvage_percentage/100,0) -> 0 | D40: =IF(D2=analysis_period,total_installed_cost*salvage_percentage/100,0) -> 0 | E40: =IF(E2=analysis_period,total_installed_cost*salvage_percentage/100,0) -> 0 | F40: =IF(F2=analysis_period,total_installed_cost*salvage_percentage/100,0) -> 0 | G40: =IF(G2=analysis_period,total_installed_cost*salvage_percentage/100,0) -> 0 | H40: =IF(H2=analysis_period,total_installed_cost*salvage_percentage/100,0) -> 0 | I40: =IF(I2=analysis_period,total_installed_cost*salvage_percentage/100,0) -> 0 | J40: =IF(J2=analysis_period,total_installed_cost*salvage_percentage/100,0) -> 0 | ... AP40: =IF(AP2=analysis_period,total_installed_cost*salvage_percentage/100,0) -> 0
A41: Total Revenue | C41: =IF(C$2<=analysis_period,C$29+SUM(C31:C33)+C$39+C$40,0) -> 0 | D41: =IF(D$2<=analysis_period,D$29+SUM(D31:D33)+D$39+D$40,0) -> 0 | E41: =IF(E$2<=analysis_period,E$29+SUM(E31:E33)+E$39+E$40,0) -> 0 | F41: =IF(F$2<=analysis_period,F$29+SUM(F31:F33)+F$39+F$40,0) -> 0 | G41: =IF(G$2<=analysis_period,G$29+SUM(G31:G33)+G$39+G$40,0) -> 0 | H41: =IF(H$2<=analysis_period,H$29+SUM(H31:H33)+H$39+H$40,0) -> 0 | I41: =IF(I$2<=analysis_period,I$29+SUM(I31:I33)+I$39+I$40,0) -> 0 | J41: =IF(J$2<=analysis_period,J$29+SUM(J31:J33)+J$39+J$40,0) -> 0 | ... AP41: =IF(AP$2<=analysis_period,AP$29+SUM(AP31:AP33)+AP$39+AP$40,0) -> 0
A43: Property tax net assessed value | C43: =PropertyTaxAssessedValue -> 0 | D43: =IF(D$2<=analysis_period,PropertyTaxAssessedValue*(100-(D$2-1)*prop_tax_assessed_decline)/100,0) -> 0 | E43: =IF(E$2<=analysis_period,PropertyTaxAssessedValue*(100-(E$2-1)*prop_tax_assessed_decline)/100,0) -> 0 | F43: =IF(F$2<=analysis_period,PropertyTaxAssessedValue*(100-(F$2-1)*prop_tax_assessed_decline)/100,0) -> 0 | G43: =IF(G$2<=analysis_period,PropertyTaxAssessedValue*(100-(G$2-1)*prop_tax_assessed_decline)/100,0) -> 0 | H43: =IF(H$2<=analysis_period,PropertyTaxAssessedValue*(100-(H$2-1)*prop_tax_assessed_decline)/100,0) -> 0 | I43: =IF(I$2<=analysis_period,PropertyTaxAssessedValue*(100-(I$2-1)*prop_tax_assessed_decline)/100,0) -> 0 | J43: =IF(J$2<=analysis_period,PropertyTaxAssessedValue*(100-(J$2-1)*prop_tax_assessed_decline)/100,0) -> 0 | K43: =IF(K$2<=analysis_period,PropertyTaxAssessedValue*(100-(K$2-1)*prop_tax_assessed_decline)/100,0) -> 0 | ... AP43: =IF(AP$2<=analysis_period,PropertyTaxAssessedValue*(100-(AP$2-1)*prop_tax_assessed_decline)/100,0) -> 0
A45: Developer Operating Expenses
...

Sheet Depreciation Schedules
A1: Depreciation Schedules (Half Year)
A2: Year | B2: 5-yr MACRS | C2: 15-yr MACRS | D2: 5-yr SL | E2: 15-yr SL | F2: 20-yr SL | G2: 39-yr SL
A3: 1 | B3: 20 | C3: 5 | D3: 10 | E3: 3.33 | F3: 2.5 | G3: =2.56410256410256*0.5 -> 1.2820513
A4: 2 | B4: 32 | C4: 9.5 | D4: 20 | E4: 6.67 | F4: 5 | G4: 2.5641026
A5: 3 | B5: 19.2 | C5: 8.55 | D5: 20 | E5: 6.67 | F5: 5 | G5: 2.5641026
A6: 4 | B6: 11.52 | C6: 7.7 | D6: 20 | E6: 6.67 | F6: 5 | G6: 2.5641026
A7: 5 | B7: 11.52 | C7: 6.93 | D7: 20 | E7: 6.67 | F7: 5 | G7: 2.5641026
A8: 6 | B8: 5.76 | C8: 6.23 | D8: 10 | E8: 6.67 | F8: 5 | G8: 2.5641026
A9: 7 | B9: 0 | C9: 5.9 | D9: 0 | E9: 6.67 | F9: 5 | G9: 2.5641026
A10: 8 | B10: 0 | C10: 5.9 | D10: 0 | E10: 6.67 | F10: 5 | G10: 2.5641026
A11: 9 | B11: 0 | C11: 5.91 | D11: 0 | E11: 6.67 | F11: 5 | G11: 2.5641026
A12: 10 | B12: 0 | C12: 5.9 | D12: 0 | E12: 6.67 | F12: 5 | G12: 2.5641026
A13: 11 | B13: 0 | C13: 5.91 | D13: 0 | E13: 6.67 | F13: 5 | G13: 2.5641026
A14: 12 | B14: 0 | C14: 5.9 | D14: 0 | E14: 6.66 | F14: 5 | G14: 2.5641026
A15: 13 | B15: 0 | C15: 5.91 | D15: 0 | E15: 6.67 | F15: 5 | G15: 2.5641026
... A41: 39 | B41: 0 | C41: 0 | D41: 0 | E41: 0 | F41: 0 | G41: 2.5641026
A42: 40 | B42: 0 | C42: 0 | D42: 0 | E42: 0 | F42: 0 | G42: =2.56410256410256*0.5 -> 1.2820513
A43: For additional information on depreciation schedules, see IRS publication 946.
A44: http://www.irs.gov/pub/irs-pdf/p946.pdf
