Workbook
Name analysis_period: Inputs!$C$38
Name annual_fuel_usage: Inputs!$C$23
Name AnnualLandLease: Inputs!$D$215
Name AnnualOMCapacity: Inputs!$D$166
Name AnnualOMFixed: Inputs!$D$165
Name AnnualOMProduction: Inputs!$D$167
Name AnnualPBIFederal: Inputs!$D$179
Name AnnualPBIOther: Inputs!$D$182
Name AnnualPBIState: Inputs!$D$180
Name AnnualPBIUtility: Inputs!$D$181
Name AnnualPTCFederal: Inputs!$D$184
Name AnnualPTCState: Inputs!$D$185
Name AnnualTaxFederal: Inputs!$C$170
Name AnnualTaxState: Inputs!$C$169
Name batt_annual_discharge_energy: Inputs!$C$153
Name CapacityPayment: Inputs!$C$34
Name cbi_fed_amount: Inputs!$C$125
Name cbi_fed_deprbas_fed: Inputs!$G$125
Name cbi_fed_deprbas_sta: Inputs!$H$125
Name cbi_fed_maxvalue: Inputs!$D$125
Name cbi_fed_tax_fed: Inputs!$E$125
Name cbi_fed_tax_sta: Inputs!$F$125
Name cbi_oth_amount: Inputs!$C$128
Name cbi_oth_deprbas_fed: Inputs!$G$128
Name cbi_oth_deprbas_sta: Inputs!$H$128
Name cbi_oth_maxvalue: Inputs!$D$128
Name cbi_oth_tax_fed: Inputs!$E$128
Name cbi_oth_tax_sta: Inputs!$F$128
Name cbi_sta_amount: Inputs!$C$126
Name cbi_sta_deprbas_fed: Inputs!$G$126
Name cbi_sta_deprbas_sta: Inputs!$H$126
Name cbi_sta_maxvalue: Inputs!$D$126
Name cbi_sta_tax_fed: Inputs!$E$126
Name cbi_sta_tax_sta: Inputs!$F$126
Name cbi_uti_amount: Inputs!$C$127
Name cbi_uti_deprbas_fed: Inputs!$G$127
Name cbi_uti_deprbas_sta: Inputs!$H$127
Name cbi_uti_maxvalue: Inputs!$D$127
Name cbi_uti_tax_fed: Inputs!$E$127
Name cbi_uti_tax_sta: Inputs!$F$127
Name cf_ancillary_services_1_revenue: Inputs!$C$157
Name cf_ancillary_services_2_revenue: Inputs!$C$158
Name cf_ancillary_services_3_revenue: Inputs!$C$159
Name cf_ancillary_services_4_revenue: Inputs!$C$160
Name cf_annual_cost_lcos: Inputs!$C$212
Name cf_annual_discharge_lcos: Inputs!$C$213
Name cf_battery_replacement_cost: Inputs!$C$192
Name cf_capacity_payment: Inputs!$C$162
Name cf_curtailment_value: Inputs!$C$161
Name cf_disbursement_debtservice: Inputs!$C$207
Name cf_energy_market_revenue: Inputs!$C$156
Name cf_energy_net: Inputs!$C$151
Name cf_energy_purchases: Inputs!$C$150
Name cf_energy_sales: Inputs!$C$149
Name cf_energy_without_battery: Inputs!$C$152
Name cf_fuelcell_replacement_cost: Inputs!$C$197
Name cf_funding_debtservice: Inputs!$C$206
Name cf_om_capacity1_expense: Inputs!$C$190
Name cf_om_capacity2_expense: Inputs!$C$195
Name cf_om_fixed1_expense: Inputs!$C$189

Sheet Inputs
B1: Merchant Plant Inputs
B2: SYSTEM DESIGN | E2: KEY
B3: Nameplate capacity (kW) | C3: 0 | E3: Calculated
E4: Input from SAM
B5: SYSTEM COSTS | E5: Annual values from SAM
B6: Total installed cost ($) | C6: 0 | E6: Value depends on option in SAM
B8: OPERATION AND MAINTENANCE COSTS | E8: METRICS
B9: Fixed annual cost ($/yr) | C9: 0 | E9: LCOE, nominal (¢/kWh) | F9: ='Cash Flow'!B150 -> 0
B10: Escalation (% above inflation) | C10: 0 | E10: NPV ($) | F10: ='Cash Flow'!B141 -> 0
B11: Fixed cost by capacity ($/kW-yr) | C11: 0 | E11: IRR (%) | F11: =HLOOKUP(F12,'Cash Flow'!B2:AP138,137) -> 0
B12: Escalation (% above inflation) | C12: 0 | E12: IRR Year | F12: =analysis_period -> 0
B13: Variable cost by generation ($/MWh) | C13: 0 | E13: IRR at end of project (%) | F13: =HLOOKUP(analysis_period,'Cash Flow'!B2:AP138,137) -> 0
B14: Escalation (% above inflation) | C14: 0 | E14: Total capital cost ($) | F14: =-'Cash Flow'!B104 -> 0
E15: Equity ($) | F15: =F14-F16 -> 0
B16: LAND LEASE | E16: Size of debt ($) | F16: ='Cash Flow'!B601 -> 0
B17: Land area estimate (acres) | C17: 0 | E17: Minimum debt service coverage ratio | F17: ='Cash Flow'!B621 -> 0
B18: Annual land lease cost ($/acre) | C18: 0 | E18: Debt fraction (%) | F18: =F16/F14*100 -> #DIV/0!
B19: Land lease escalation rate (% above inflation) | C19: 0
B21: FUEL COSTS (CSP, GENERIC, AND BIOPOWER SYSTEMS ONLY)
B22: Fuel (CSP and generic system only)
B23: Annual usage (kWh) | C23: 0
B24: Heat rate (MMBtu/MWh) | C24: 0
B25: Cost ($/MMBtu) | C25: 0
B26: Escalation (%/year above inflation) | C26: 0
B28: Revenue Sources
B29: Energy market | C29: 1
B30: Ancillary service 1 | C30: 0
B31: Ancillary service 2 | C31: 0
B32: Ancillary service 3 | C32: 0
B33: Ancillary service 4 | C33: 0
B34: Capacity payment | C34: 0
B36: FINANCIAL PARAMETERS
B37: Analysis Parameters
B38: Analysis period (years, 40 max) | C38: 0
B39: Inflation rate (%/year) | C39: 0
B40: Real discount rate (%/year) | C40: 0
B41: Nominal discount rate (%/year) | C41: =((inflation_rate/100+1)*(real_discount_rate/100+1)-1)*100 -> 0
B42: Tax and Insurance Rates
B43: Federal income tax rate in Year 1 (%/year) | C43: =AnnualTaxFederal -> 0
B44: State income tax rate in Year 1 (%/year) | C44: =AnnualTaxState -> 0
...

Sheet Cash Flow
A1: Merchant Plant Cash Flow
A2: Operating Year | B2: 0 | C2: =IF(B2<analysis_period,B2+1,"") | D2: =IF(C2<analysis_period,C2+1,"") | E2: =IF(D2<analysis_period,D2+1,"") | F2: =IF(E2<analysis_period,E2+1,"") | G2: =IF(F2<analysis_period,F2+1,"") | H2: =IF(G2<analysis_period,G2+1,"") | I2: =IF(H2<analysis_period,H2+1,"") | J2: =IF(I2<analysis_period,I2+1,"") | ... AP2: =IF(AO2<analysis_period,AO2+1,"")
A4: Energy
A5: Electricity to grid (AC kWh) | B5: {=Inputs!C149:AQ150} -> 0 | C5: 0 | D5: 0 | E5: 0 | F5: 0 | G5: 0 | H5: 0 | I5: 0 | J5: 0 | K5: 0 | L5: 0 | M5: 0 | N5: 0 | O5: 0 | P5: 0 | Q5: 0 | R5: 0 | S5: 0 | T5: 0 | U5: 0 | V5: 0 | W5: 0 | X5: 0 | Y5: 0 | Z5: 0 | AA5: 0 | AB5: 0 | AC5: 0 | AD5: 0 | AE5: 0 | AF5: 0 | AG5: 0 | AH5: 0 | AI5: 0 | AJ5: 0 | AK5: 0 | AL5: 0 | AM5: 0 | AN5: 0 | AO5: 0 | AP5: 0
A6: Electricity from grid (AC kWh) | B6: 0 | C6: 0 | D6: 0 | E6: 0 | F6: 0 | G6: 0 | H6: 0 | I6: 0 | J6: 0 | K6: 0 | L6: 0 | M6: 0 | N6: 0 | O6: 0 | P6: 0 | Q6: 0 | R6: 0 | S6: 0 | T6: 0 | U6: 0 | V6: 0 | W6: 0 | X6: 0 | Y6: 0 | Z6: 0 | AA6: 0 | AB6: 0 | AC6: 0 | AD6: 0 | AE6: 0 | AF6: 0 | AG6: 0 | AH6: 0 | AI6: 0 | AJ6: 0 | AK6: 0 | AL6: 0 | AM6: 0 | AN6: 0 | AO6: 0 | AP6: 0
A7: Electricity to grid net (AC kWh) | B7: =SUM(B$5:B$6) -> 0 | C7: =SUM(C5:C6) -> 0 | D7: =SUM(D5:D6) -> 0 | E7: =SUM(E5:E6) -> 0 | F7: =SUM(F5:F6) -> 0 | G7: =SUM(G5:G6) -> 0 | H7: =SUM(H5:H6) -> 0 | I7: =SUM(I5:I6) -> 0 | J7: =SUM(J5:J6) -> 0 | ... AP7: =SUM(AP5:AP6) -> 0
A8: Electricity generated without storage (AC kWh) | B8: {=Inputs!C152:AQ154} -> 0 | C8: 0 | D8: 0 | E8: 0 | F8: 0 | G8: 0 | H8: 0 | I8: 0 | J8: 0 | K8: 0 | L8: 0 | M8: 0 | N8: 0 | O8: 0 | P8: 0 | Q8: 0 | R8: 0 | S8: 0 | T8: 0 | U8: 0 | V8: 0 | W8: 0 | X8: 0 | Y8: 0 | Z8: 0 | AA8: 0 | AB8: 0 | AC8: 0 | AD8: 0 | AE8: 0 | AF8: 0 | AG8: 0 | AH8: 0 | AI8: 0 | AJ8: 0 | AK8: 0 | AL8: 0 | AM8: 0 | AN8: 0 | AO8: 0 | AP8: 0
A9: Battery annual energy discharged (AC kWh) | B9: 0 | C9: 0 | D9: 0 | E9: 0 | F9: 0 | G9: 0 | H9: 0 | I9: 0 | J9: 0 | K9: 0 | L9: 0 | M9: 0 | N9: 0 | O9: 0 | P9: 0 | Q9: 0 | R9: 0 | S9: 0 | T9: 0 | U9: 0 | V9: 0 | W9: 0 | X9: 0 | Y9: 0 | Z9: 0 | AA9: 0 | AB9: 0 | AC9: 0 | AD9: 0 | AE9: 0 | AF9: 0 | AG9: 0 | AH9: 0 | AI9: 0 | AJ9: 0 | AK9: 0 | AL9: 0 | AM9: 0 | AN9: 0 | AO9: 0 | AP9: 0
A10: Fuel cell annual energy discharged (AC kWh) | B10: 0 | C10: 0 | D10: 0 | E10: 0 | F10: 0 | G10: 0 | H10: 0 | I10: 0 | J10: 0 | K10: 0 | L10: 0 | M10: 0 | N10: 0 | O10: 0 | P10: 0 | Q10: 0 | R10: 0 | S10: 0 | T10: 0 | U10: 0 | V10: 0 | W10: 0 | X10: 0 | Y10: 0 | Z10: 0 | AA10: 0 | AB10: 0 | AC10: 0 | AD10: 0 | AE10: 0 | AF10: 0 | AG10: 0 | AH10: 0 | AI10: 0 | AJ10: 0 | AK10: 0 | AL10: 0 | AM10: 0 | AN10: 0 | AO10: 0 | AP10: 0
A12: Revenue
A13: Energy and Capacity Revenue
A14: Energy market | B14: {=Inputs!C156:AQ156} -> 0 | C14: 0 | D14: 0 | E14: 0 | F14: 0 | G14: 0 | H14: 0 | I14: 0 | J14: 0 | K14: 0 | L14: 0 | M14: 0 | N14: 0 | O14: 0 | P14: 0 | Q14: 0 | R14: 0 | S14: 0 | T14: 0 | U14: 0 | V14: 0 | W14: 0 | X14: 0 | Y14: 0 | Z14: 0 | AA14: 0 | AB14: 0 | AC14: 0 | AD14: 0 | AE14: 0 | AF14: 0 | AG14: 0 | AH14: 0 | AI14: 0 | AJ14: 0 | AK14: 0 | AL14: 0 | AM14: 0 | AN14: 0 | AO14: 0 | AP14: 0
A15: Ancillary service 1 | B15: {=Inputs!C157:AQ157} -> 0 | C15: 0 | D15: 0 | E15: 0 | F15: 0 | G15: 0 | H15: 0 | I15: 0 | J15: 0 | K15: 0 | L15: 0 | M15: 0 | N15: 0 | O15: 0 | P15: 0 | Q15: 0 | R15: 0 | S15: 0 | T15: 0 | U15: 0 | V15: 0 | W15: 0 | X15: 0 | Y15: 0 | Z15: 0 | AA15: 0 | AB15: 0 | AC15: 0 | AD15: 0 | AE15: 0 | AF15: 0 | AG15: 0 | AH15: 0 | AI15: 0 | AJ15: 0 | AK15: 0 | AL15: 0 | AM15: 0 | AN15: 0 | AO15: 0 | AP15: 0
A16: Ancillary service 2 | B16: {=Inputs!C158:AQ158} -> 0 | C16: 0 | D16: 0 | E16: 0 | F16: 0 | G16: 0 | H16: 0 | I16: 0 | J16: 0 | K16: 0 | L16: 0 | M16: 0 | N16: 0 | O16: 0 | P16: 0 | Q16: 0 | R16: 0 | S16: 0 | T16: 0 | U16: 0 | V16: 0 | W16: 0 | X16: 0 | Y16: 0 | Z16: 0 | AA16: 0 | AB16: 0 | AC16: 0 | AD16: 0 | AE16: 0 | AF16: 0 | AG16: 0 | AH16: 0 | AI16: 0 | AJ16: 0 | AK16: 0 | AL16: 0 | AM16: 0 | AN16: 0 | AO16: 0 | AP16: 0
A17: Ancillary service 3 | B17: {=Inputs!C159:AQ159} -> 0 | C17: 0 | D17: 0 | E17: 0 | F17: 0 | G17: 0 | H17: 0 | I17: 0 | J17: 0 | K17: 0 | L17: 0 | M17: 0 | N17: 0 | O17: 0 | P17: 0 | Q17: 0 | R17: 0 | S17: 0 | T17: 0 | U17: 0 | V17: 0 | W17: 0 | X17: 0 | Y17: 0 | Z17: 0 | AA17: 0 | AB17: 0 | AC17: 0 | AD17: 0 | AE17: 0 | AF17: 0 | AG17: 0 | AH17: 0 | AI17: 0 | AJ17: 0 | AK17: 0 | AL17: 0 | AM17: 0 | AN17: 0 | AO17: 0 | AP17: 0
A18: Ancillary service 4 | B18: {=Inputs!C160:AQ160} -> 0 | C18: 0 | D18: 0 | E18: 0 | F18: 0 | G18: 0 | H18: 0 | I18: 0 | J18: 0 | K18: 0 | L18: 0 | M18: 0 | N18: 0 | O18: 0 | P18: 0 | Q18: 0 | R18: 0 | S18: 0 | T18: 0 | U18: 0 | V18: 0 | W18: 0 | X18: 0 | Y18: 0 | Z18: 0 | AA18: 0 | AB18: 0 | AC18: 0 | AD18: 0 | AE18: 0 | AF18: 0 | AG18: 0 | AH18: 0 | AI18: 0 | AJ18: 0 | AK18: 0 | AL18: 0 | AM18: 0 | AN18: 0 | AO18: 0 | AP18: 0
A19: Curtailment payments | B19: {=Inputs!C161:AQ163} -> 0 | C19: 0 | D19: 0 | E19: 0 | F19: 0 | G19: 0 | H19: 0 | I19: 0 | J19: 0 | K19: 0 | L19: 0 | M19: 0 | N19: 0 | O19: 0 | P19: 0 | Q19: 0 | R19: 0 | S19: 0 | T19: 0 | U19: 0 | V19: 0 | W19: 0 | X19: 0 | Y19: 0 | Z19: 0 | AA19: 0 | AB19: 0 | AC19: 0 | AD19: 0 | AE19: 0 | AF19: 0 | AG19: 0 | AH19: 0 | AI19: 0 | AJ19: 0 | AK19: 0 | AL19: 0 | AM19: 0 | AN19: 0 | AO19: 0 | AP19: 0
A20: Capacity payments | B20: 0 | C20: 0 | D20: 0 | E20: 0 | F20: 0 | G20: 0 | H20: 0 | I20: 0 | J20: 0 | K20: 0 | L20: 0 | M20: 0 | N20: 0 | O20: 0 | P20: 0 | Q20: 0 | R20: 0 | S20: 0 | T20: 0 | U20: 0 | V20: 0 | W20: 0 | X20: 0 | Y20: 0 | Z20: 0 | AA20: 0 | AB20: 0 | AC20: 0 | AD20: 0 | AE20: 0 | AF20: 0 | AG20: 0 | AH20: 0 | AI20: 0 | AJ20: 0 | AK20: 0 | AL20: 0 | AM20: 0 | AN20: 0 | AO20: 0 | AP20: 0
A21: Thermal revenue (fuel cell only) | B21: 0 | C21: 0 | D21: 0 | E21: 0 | F21: 0 | G21: 0 | H21: 0 | I21: 0 | J21: 0 | K21: 0 | L21: 0 | M21: 0 | N21: 0 | O21: 0 | P21: 0 | Q21: 0 | R21: 0 | S21: 0 | T21: 0 | U21: 0 | V21: 0 | W21: 0 | X21: 0 | Y21: 0 | Z21: 0 | AA21: 0 | AB21: 0 | AC21: 0 | AD21: 0 | AE21: 0 | AF21: 0 | AG21: 0 | AH21: 0 | AI21: 0 | AJ21: 0 | AK21: 0 | AL21: 0 | AM21: 0 | AN21: 0 | AO21: 0 | AP21: 0
A22: Subtotal revenue | C22: =SUM(C14:C21) -> 0 | D22: =SUM(D14:D21) -> 0 | E22: =SUM(E14:E21) -> 0 | F22: =SUM(F14:F21) -> 0 | G22: =SUM(G14:G21) -> 0 | H22: =SUM(H14:H21) -> 0 | I22: =SUM(I14:I21) -> 0 | J22: =SUM(J14:J21) -> 0 | ... AP22: =SUM(AP14:AP21) -> 0
A23: Production Based Incentive (included if available for debt service)
A24: Federal | C24: =IF(pbi_fed_for_ds="Yes",C580,0) -> 0 | D24: =IF(pbi_fed_for_ds="Yes",D580,0) -> 0 | E24: =IF(pbi_fed_for_ds="Yes",E580,0) -> 0 | F24: =IF(pbi_fed_for_ds="Yes",F580,0) -> 0 | G24: =IF(pbi_fed_for_ds="Yes",G580,0) -> 0 | H24: =IF(pbi_fed_for_ds="Yes",H580,0) -> 0 | I24: =IF(pbi_fed_for_ds="Yes",I580,0) -> 0 | J24: =IF(pbi_fed_for_ds="Yes",J580,0) -> 0 | ... AP24: =IF(pbi_fed_for_ds="Yes",AP580,0) -> 0
A25: State | C25: =IF(pbi_sta_for_ds="Yes",C584,0) -> 0 | D25: =IF(pbi_sta_for_ds="Yes",D584,0) -> 0 | E25: =IF(pbi_sta_for_ds="Yes",E584,0) -> 0 | F25: =IF(pbi_sta_for_ds="Yes",F584,0) -> 0 | G25: =IF(pbi_sta_for_ds="Yes",G584,0) -> 0 | H25: =IF(pbi_sta_for_ds="Yes",H584,0) -> 0 | I25: =IF(pbi_sta_for_ds="Yes",I584,0) -> 0 | J25: =IF(pbi_sta_for_ds="Yes",J584,0) -> 0 | ... AP25: =IF(pbi_sta_for_ds="Yes",AP584,0) -> 0
A26: Utility | C26: =IF(pbi_uti_for_ds="Yes",C588,0) -> 0 | D26: =IF(pbi_uti_for_ds="Yes",D588,0) -> 0 | E26: =IF(pbi_uti_for_ds="Yes",E588,0) -> 0 | F26: =IF(pbi_uti_for_ds="Yes",F588,0) -> 0 | G26: =IF(pbi_uti_for_ds="Yes",G588,0) -> 0 | H26: =IF(pbi_uti_for_ds="Yes",H588,0) -> 0 | I26: =IF(pbi_uti_for_ds="Yes",I588,0) -> 0 | J26: =IF(pbi_uti_for_ds="Yes",J588,0) -> 0 | ... AP26: =IF(pbi_uti_for_ds="Yes",AP588,0) -> 0
A27: Other | C27: =IF(pbi_oth_for_ds="Yes",C592,0) -> 0 | D27: =IF(pbi_oth_for_ds="Yes",D592,0) -> 0 | E27: =IF(pbi_oth_for_ds="Yes",E592,0) -> 0 | F27: =IF(pbi_oth_for_ds="Yes",F592,0) -> 0 | G27: =IF(pbi_oth_for_ds="Yes",G592,0) -> 0 | H27: =IF(pbi_oth_for_ds="Yes",H592,0) -> 0 | I27: =IF(pbi_oth_for_ds="Yes",I592,0) -> 0 | J27: =IF(pbi_oth_for_ds="Yes",J592,0) -> 0 | ... AP27: =IF(pbi_oth_for_ds="Yes",AP592,0) -> 0
A28: Subtotal PBI | C28: =SUM(C24:C27) -> 0 | D28: =SUM(D24:D27) -> 0 | E28: =SUM(E24:E27) -> 0 | F28: =SUM(F24:F27) -> 0 | G28: =SUM(G24:G27) -> 0 | H28: =SUM(H24:H27) -> 0 | I28: =SUM(I24:I27) -> 0 | J28: =SUM(J24:J27) -> 0 | ... AP28: =SUM(AP24:AP27) -> 0
A29: Salvage value | C29: =IF(C2=analysis_period,total_installed_cost*salvage_percentage/100,0) -> 0 | D29: =IF(D2=analysis_period,total_installed_cost*salvage_percentage/100,0) -> 0 | E29: =IF(E2=analysis_period,total_installed_cost*salvage_percentage/100,0) -> 0 | F29: =IF(F2=analysis_period,total_installed_cost*salvage_percentage/100,0) -> 0 | G29: =IF(G2=analysis_period,total_installed_cost*salvage_percentage/100,0) -> 0 | H29: =IF(H2=analysis_period,total_installed_cost*salvage_percentage/100,0) -> 0 | I29: =IF(I2=analysis_period,total_installed_cost*salvage_percentage/100,0) -> 0 | J29: =IF(J2=analysis_period,total_installed_cost*salvage_percentage/100,0) -> 0 | ... AP29: =IF(AP2=analysis_period,total_installed_cost*salvage_percentage/100,0) -> 0
A30: Total Revenue | C30: =IF(C2<=analysis_period,C22+C28+C29,0) -> 0 | D30: =IF(D2<=analysis_period,D22+D28+D29,0) -> 0 | E30: =IF(E2<=analysis_period,E22+E28+E29,0) -> 0 | F30: =IF(F2<=analysis_period,F22+F28+F29,0) -> 0 | G30: =IF(G2<=analysis_period,G22+G28+G29,0) -> 0 | H30: =IF(H2<=analysis_period,H22+H28+H29,0) -> 0 | I30: =IF(I2<=analysis_period,I22+I28+I29,0) -> 0 | J30: =IF(J2<=analysis_period,J22+J28+J29,0) -> 0 | ... AP30: =IF(AP2<=analysis_period,AP22+AP28+AP29,0) -> 0
A32: Property tax net assessed value | C32: =PropertyTaxAssessedValue -> 0 | D32: =IF(D2<=analysis_period,PropertyTaxAssessedValue*(100-(D$2-1)*prop_tax_assessed_decline)/100,0) -> 0 | E32: =IF(E2<=analysis_period,PropertyTaxAssessedValue*(100-(E$2-1)*prop_tax_assessed_decline)/100,0) -> 0 | F32: =IF(F2<=analysis_period,PropertyTaxAssessedValue*(100-(F$2-1)*prop_tax_assessed_decline)/100,0) -> 0 | G32: =IF(G2<=analysis_period,PropertyTaxAssessedValue*(100-(G$2-1)*prop_tax_assessed_decline)/100,0) -> 0 | H32: =IF(H2<=analysis_period,PropertyTaxAssessedValue*(100-(H$2-1)*prop_tax_assessed_decline)/100,0) -> 0 | I32: =IF(I2<=analysis_period,PropertyTaxAssessedValue*(100-(I$2-1)*prop_tax_assessed_decline)/100,0) -> 0 | J32: =IF(J2<=analysis_period,PropertyTaxAssessedValue*(100-(J$2-1)*prop_tax_assessed_decline)/100,0) -> 0 | K32: =IF(K2<=analysis_period,PropertyTaxAssessedValue*(100-(K$2-1)*prop_tax_assessed_decline)/100,0) -> 0 | ... AP32: =IF(AP2<=analysis_period,PropertyTaxAssessedValue*(100-(AP$2-1)*prop_tax_assessed_decline)/100,0) -> 0
A34: Operating Expenses
A35: Operation and maintenance (O&M)
A36: Fixed | C36: =IF(C$2<=analysis_period,IF(om_fixed="n/a",Inputs!D165,om_fixed*(1+inflation_rate/100+om_fixed_escal/100)^B$2),0) -> 0 | D36: =IF(D$2<=analysis_period,IF(om_fixed="n/a",Inputs!E165,om_fixed*(1+inflation_rate/100+om_fixed_escal/100)^C$2),0) -> 0 | E36: =IF(E$2<=analysis_period,IF(om_fixed="n/a",Inputs!F165,om_fixed*(1+inflation_rate/100+om_fixed_escal/100)^D$2),0) -> 0 | F36: =IF(F$2<=analysis_period,IF(om_fixed="n/a",Inputs!G165,om_fixed*(1+inflation_rate/100+om_fixed_escal/100)^E$2),0) -> 0 | G36: =IF(G$2<=analysis_period,IF(om_fixed="n/a",Inputs!H165,om_fixed*(1+inflation_rate/100+om_fixed_escal/100)^F$2),0) -> 0 | H36: =IF(H$2<=analysis_period,IF(om_fixed="n/a",Inputs!I165,om_fixed*(1+inflation_rate/100+om_fixed_escal/100)^G$2),0) -> 0 | I36: =IF(I$2<=analysis_period,IF(om_fixed="n/a",Inputs!J165,om_fixed*(1+inflation_rate/100+om_fixed_escal/100)^H$2),0) -> 0 | J36: =IF(J$2<=analysis_period,IF(om_fixed="n/a",Inputs!K165,om_fixed*(1+inflation_rate/100+om_fixed_escal/100)^I$2),0) -> 0 | ... AP36: =IF(AP$2<=analysis_period,IF(om_fixed="n/a",Inputs!AQ165,om_fixed*(1+inflation_rate/100+om_fixed_escal/100)^AO$2),0) -> 0
A37: Capacity
A38: Capacity (DC kW) | C38: =IF(C$2<=analysis_period,system_capacity,0) -> 0 | D38: =IF(D$2<=analysis_period,system_capacity,0) -> 0 | E38: =IF(E$2<=analysis_period,system_capacity,0) -> 0 | F38: =IF(F$2<=analysis_period,system_capacity,0) -> 0 | G38: =IF(G$2<=analysis_period,system_capacity,0) -> 0 | H38: =IF(H$2<=analysis_period,system_capacity,0) -> 0 | I38: =IF(I$2<=analysis_period,system_capacity,0) -> 0 | J38: =IF(J$2<=analysis_period,system_capacity,0) -> 0 | ... AP38: =IF(AP$2<=analysis_period,system_capacity,0) -> 0
A39: Fixed Cost ($/DC kW-yr) | C39: =IF(C$2<=analysis_period,IF(om_capacity="n/a",Inputs!D166,om_capacity*(1+inflation_rate/100+om_capacity_escal/100)^B$2),0) -> 0 | D39: =IF(D$2<=analysis_period,IF(om_capacity="n/a",Inputs!E166,om_capacity*(1+inflation_rate/100+om_capacity_escal/100)^C$2),0) -> 0 | E39: =IF(E$2<=analysis_period,IF(om_capacity="n/a",Inputs!F166,om_capacity*(1+inflation_rate/100+om_capacity_escal/100)^D$2),0) -> 0 | F39: =IF(F$2<=analysis_period,IF(om_capacity="n/a",Inputs!G166,om_capacity*(1+inflation_rate/100+om_capacity_escal/100)^E$2),0) -> 0 | G39: =IF(G$2<=analysis_period,IF(om_capacity="n/a",Inputs!H166,om_capacity*(1+inflation_rate/100+om_capacity_escal/100)^F$2),0) -> 0 | H39: =IF(H$2<=analysis_period,IF(om_capacity="n/a",Inputs!I166,om_capacity*(1+inflation_rate/100+om_capacity_escal/100)^G$2),0) -> 0 | I39: =IF(I$2<=analysis_period,IF(om_capacity="n/a",Inputs!J166,om_capacity*(1+inflation_rate/100+om_capacity_escal/100)^H$2),0) -> 0 | J39: =IF(J$2<=analysis_period,IF(om_capacity="n/a",Inputs!K166,om_capacity*(1+inflation_rate/100+om_capacity_escal/100)^I$2),0) -> 0 | ... AP39: =IF(AP$2<=analysis_period,IF(om_capacity="n/a",Inputs!AQ166,om_capacity*(1+inflation_rate/100+om_capacity_escal/100)^AO$2),0) -> 0
A40: O&M capacity-based expense | C40: =C38*C39 -> 0 | D40: =D38*D39 -> 0 | E40: =E38*E39 -> 0 | F40: =F38*F39 -> 0 | G40: =G38*G39 -> 0 | H40: =H38*H39 -> 0 | I40: =I38*I39 -> 0 | J40: =J38*J39 -> 0 | ... AP40: =AP38*AP39 -> 0
A41: Variable
A42: Generation (AC-MWh) | C42: =IF(C$8=0,C$5,C$8)/1000 -> 0 | D42: =IF(D$8=0,D$5,D$8)/1000 -> 0 | E42: =IF(E$8=0,E$5,E$8)/1000 -> 0 | F42: =IF(F$8=0,F$5,F$8)/1000 -> 0 | G42: =IF(G$8=0,G$5,G$8)/1000 -> 0 | H42: =IF(H$8=0,H$5,H$8)/1000 -> 0 | I42: =IF(I$8=0,I$5,I$8)/1000 -> 0 | J42: =IF(J$8=0,J$5,J$8)/1000 -> 0 | ... AP42: =IF(AP$8=0,AP$5,AP$8)/1000 -> 0
A43: Variable Cost ($/AC-MWh) | C43: =IF(C$2<=analysis_period,IF(om_production="n/a",Inputs!D167,om_production*(1+inflation_rate/100+om_production_escal/100)^B$2),0) -> 0 | D43: =IF(D$2<=analysis_period,IF(om_production="n/a",Inputs!E167,om_production*(1+inflation_rate/100+om_production_escal/100)^C$2),0) -> 0 | E43: =IF(E$2<=analysis_period,IF(om_production="n/a",Inputs!F167,om_production*(1+inflation_rate/100+om_production_escal/100)^D$2),0) -> 0 | F43: =IF(F$2<=analysis_period,IF(om_production="n/a",Inputs!G167,om_production*(1+inflation_rate/100+om_production_escal/100)^E$2),0) -> 0 | G43: =IF(G$2<=analysis_period,IF(om_production="n/a",Inputs!H167,om_production*(1+inflation_rate/100+om_production_escal/100)^F$2),0) -> 0 | H43: =IF(H$2<=analysis_period,IF(om_production="n/a",Inputs!I167,om_production*(1+inflation_rate/100+om_production_escal/100)^G$2),0) -> 0 | I43: =IF(I$2<=analysis_period,IF(om_production="n/a",Inputs!J167,om_production*(1+inflation_rate/100+om_production_escal/100)^H$2),0) -> 0 | J43: =IF(J$2<=analysis_period,IF(om_production="n/a",Inputs!K167,om_production*(1+inflation_rate/100+om_production_escal/100)^I$2),0) -> 0 | ... AP43: =IF(AP$2<=analysis_period,IF(om_production="n/a",Inputs!AQ167,om_production*(1+inflation_rate/100+om_production_escal/100)^AO$2),0) -> 0
A44: O&M production-based expense | C44: =C42*C43 -> 0 | D44: =D42*D43 -> 0 | E44: =E42*E43 -> 0 | F44: =F42*F43 -> 0 | G44: =G42*G43 -> 0 | H44: =H42*H43 -> 0 | I44: =I42*I43 -> 0 | J44: =J42*J43 -> 0 | ... AP44: =AP42*AP43 -> 0
...

Sheet Depreciation Schedules
A1: Depreciation Schedules (Half Year)
A2: Year | B2: 5-yr MACRS | C2: 15-yr MACRS | D2: 5-yr SL | E2: 15-yr SL | F2: 20-yr SL | G2: 39-yr SL
A3: 1 | B3: 20 | C3: 5 | D3: 10 | E3: 3.33 | F3: 2.5 | G3: =2.56410256410256*0.5 -> 1.2820513
A4: 2 | B4: 32 | C4: 9.5 | D4: 20 | E4: 6.67 | F4: 5 | G4: 2.5641026
A5: 3 | B5: 19.2 | C5: 8.55 | D5: 20 | E5: 6.67 | F5: 5 | G5: 2.5641026
A6: 4 | B6: 11.52 | C6: 7.7 | D6: 20 | E6: 6.67 | F6: 5 | G6: 2.5641026
A7: 5 | B7: 11.52 | C7: 6.93 | D7: 20 | E7: 6.67 | F7: 5 | G7: 2.5641026
A8: 6 | B8: 5.76 | C8: 6.23 | D8: 10 | E8: 6.67 | F8: 5 | G8: 2.5641026
A9: 7 | B9: 0 | C9: 5.9 | D9: 0 | E9: 6.67 | F9: 5 | G9: 2.5641026
A10: 8 | B10: 0 | C10: 5.9 | D10: 0 | E10: 6.67 | F10: 5 | G10: 2.5641026
A11: 9 | B11: 0 | C11: 5.91 | D11: 0 | E11: 6.67 | F11: 5 | G11: 2.5641026
A12: 10 | B12: 0 | C12: 5.9 | D12: 0 | E12: 6.67 | F12: 5 | G12: 2.5641026
A13: 11 | B13: 0 | C13: 5.91 | D13: 0 | E13: 6.67 | F13: 5 | G13: 2.5641026
A14: 12 | B14: 0 | C14: 5.9 | D14: 0 | E14: 6.66 | F14: 5 | G14: 2.5641026
A15: 13 | B15: 0 | C15: 5.91 | D15: 0 | E15: 6.67 | F15: 5 | G15: 2.5641026
... A41: 39 | B41: 0 | C41: 0 | D41: 0 | E41: 0 | F41: 0 | G41: 2.5641026
A42: 40 | B42: 0 | C42: 0 | D42: 0 | E42: 0 | F42: 0 | G42: =2.56410256410256*0.5 -> 1.2820513
A43: For additional information on depreciation schedules, see IRS publication 946.
A44: http://www.irs.gov/pub/irs-pdf/p946.pdf
A45: * Note custom schedule is defined on Inputs sheet around Row 180
