Workbook
Name analysis_period: Inputs!$C$47
Name annual_fuel_usage: Inputs!$C$19
Name AnnualLandLease: Inputs!$D$225
Name AnnualOMCapacity: Inputs!$D$176
Name AnnualOMFixed: Inputs!$D$175
Name AnnualOMProduction: Inputs!$D$177
Name AnnualPBIFederal: Inputs!$D$189
Name AnnualPBIOther: Inputs!$D$192
Name AnnualPBIState: Inputs!$D$190
Name AnnualPBIUtility: Inputs!$D$191
Name AnnualPTCFederal: Inputs!$D$194
Name AnnualPTCState: Inputs!$D$195
Name AnnualTaxFederal: Inputs!$C$180
Name AnnualTaxState: Inputs!$C$179
Name batt_annual_discharge_energy: Inputs!$C$166
Name cbi_fed_amount: Inputs!$C$138
Name cbi_fed_deprbas_fed: Inputs!$G$138
Name cbi_fed_deprbas_sta: Inputs!$H$138
Name cbi_fed_maxvalue: Inputs!$D$138
Name cbi_fed_tax_fed: Inputs!$E$138
Name cbi_fed_tax_sta: Inputs!$F$138
Name cbi_oth_amount: Inputs!$C$141
Name cbi_oth_deprbas_fed: Inputs!$G$141
Name cbi_oth_deprbas_sta: Inputs!$H$141
Name cbi_oth_maxvalue: Inputs!$D$141
Name cbi_oth_tax_fed: Inputs!$E$141
Name cbi_oth_tax_sta: Inputs!$F$141
Name cbi_sta_amount: Inputs!$C$139
Name cbi_sta_deprbas_fed: Inputs!$G$139
Name cbi_sta_deprbas_sta: Inputs!$H$139
Name cbi_sta_maxvalue: Inputs!$D$139
Name cbi_sta_tax_fed: Inputs!$E$139
Name cbi_sta_tax_sta: Inputs!$F$139
Name cbi_uti_amount: Inputs!$C$140
Name cbi_uti_deprbas_fed: Inputs!$G$140
Name cbi_uti_deprbas_sta: Inputs!$H$140
Name cbi_uti_maxvalue: Inputs!$D$140
Name cbi_uti_tax_fed: Inputs!$E$140
Name cbi_uti_tax_sta: Inputs!$F$140
Name cf_annual_cost_lcos: Inputs!$C$222
Name cf_annual_discharge_lcos: Inputs!$C$223
Name cf_battery_replacement_cost: Inputs!$C$202
Name cf_capacity_payment: Inputs!$C$171
Name cf_curtailment_value: Inputs!$C$172
Name cf_disbursement_debtservice: Inputs!$C$217
Name cf_energy_net: Inputs!$C$164
Name cf_energy_purchases: Inputs!$C$163
Name cf_energy_sales: Inputs!$C$162
Name cf_energy_value: Inputs!$C$170
Name cf_energy_without_battery: Inputs!$C$165
Name cf_fuelcell_replacement_cost: Inputs!$C$207
Name cf_funding_debtservice: Inputs!$C$216
Name cf_om_capacity1_expense: Inputs!$C$200
Name cf_om_capacity2_expense: Inputs!$C$205
Name cf_om_fixed1_expense: Inputs!$C$199
Name cf_om_fixed2_expense: Inputs!$C$204
Name cf_om_fuel_expense: Inputs!$C$210
Name cf_om_opt_fuel_1_expense: Inputs!$C$211
Name cf_om_opt_fuel_2_expense: Inputs!$C$212
Name cf_om_production1_expense: Inputs!$C$201

Sheet Inputs
B1: Partnership Flip Inputs
B2: SYSTEM DESIGN | E2: KEY
B3: Nameplate capacity (kW) | C3: 0 | E3: Calculated
E4: Input from SAM
B5: SYSTEM COSTS | E5: Annual values from SAM
B6: Total installed cost ($) | C6: 0 | E6: Value depends on option in SAM
B8: OPERATION AND MAINTENANCE COSTS | E8: METRICS
B9: Fixed annual cost ($/yr) | C9: 0 | E9: PPA price, year 1 (¢/kWh) | F9: ='Cash Flow'!C16 -> 0
B10: Escalation (% above inflation) | C10: 0 | E10: PPA price escalation (%/yr) | F10: =ppa_escalation -> 0
B11: Fixed cost by capacity ($/kW-yr) | C11: 0 | E11: Levelized PPA price nominal (¢/kWh) | F11: ='Cash Flow'!B152 -> 0
B12: Escalation (% above inflation) | C12: 0 | E12: LCOE, nominal (¢/kWh) | F12: ='Cash Flow'!B148 -> 0
B13: Variable cost by generation ($/MWh) | C13: 0 | E13: Investor IRR (%) | F13: =HLOOKUP(IF(PPAPriceInput="Calculated",flip_actual_year,F14),'Cash Flow'!B2:AP202,201) -> 0
B14: Escalation (% above inflation) | C14: 0 | E14: Investor IRR year | F14: =flip_actual_year -> 0
E15: Investor IRR at end of project (%) | F15: =HLOOKUP(analysis_period,'Cash Flow'!B2:AP202,201) -> 0
E16: Investor NPV | F16: ='Cash Flow'!B205 -> 0
B17: FUEL COSTS (CSP, GENERIC, AND BIOPOWER SYSTEMS ONLY) | E17: Developer IRR at end of project (%) | F17: =HLOOKUP(analysis_period,'Cash Flow'!B2:AP184,183) -> 0
B18: Fuel (CSP and generic system only) | E18: Developer NPV | F18: ='Cash Flow'!B186 -> 0
B19: Annual usage (kWh) | C19: 0 | E19: Total capital cost ($) | F19: =-'Cash Flow'!B105 -> 0
B20: Heat rate (MMBtu/MWh) | C20: 0 | E20: Equity ($) | F20: =F19-F21 -> 0
B21: Cost ($/MMBtu) | C21: 0 | E21: Size of debt ($) | F21: ='Cash Flow'!B645 -> 0
B22: Escalation (%/year above inflation) | C22: 0 | E22: Minimum debt service coverage ratio | F22: ='Cash Flow'!B665 -> 0
E23: Debt fraction (%) | F23: =F21/F19*100 -> #DIV/0!
B24: LAND LEASE
B25: Land area estimate (acres) | C25: 0
B26: Annual land lease cost ($/acre) | C26: 0
B27: Land lease escalation rate (% above inflation) | C27: 0
B29: FINANCIAL PARAMETERS
B30: Solution Mode
B31: Tax investor IRR target | C31: 0
B32: Actual flip year | C32: 0
B33: Target year | C33: 0
B34: PPA price ($/kWh) | C34: Calculated
B35: PPA priced escalation (%/year) | C35: 0
B36: PPA price is modified by TOD multipliers | C36: No
B37: Equity Flip Structure | D37: Developer share
B38: Tax investor share of equity (%) | C38: 0 | D38: =100-C38 -> 100
B39: Tax investor share of project cash pre-flip (%) | C39: 0 | D39: =100-C39 -> 100
B40: Tax investor share of project cash post-flip (%) | C40: 0 | D40: =100-C40 -> 100
B41: Tax investor share of tax benefits pre-flip (%) | C41: 0 | D41: =100-C41 -> 100
B42: Tax investor share of tax benefits post-flip (%) | C42: 0 | D42: =100-C42 -> 100
...

Sheet Cash Flow
A1: Partnership Flip Cash Flow
A2: Operating Year | B2: 0 | C2: =IF(B2="","",IF(B2+1<=analysis_period,B2+1,"")) | D2: =IF(C2="","",IF(C2+1<=analysis_period,C2+1,"")) | E2: =IF(D2="","",IF(D2+1<=analysis_period,D2+1,"")) | F2: =IF(E2="","",IF(E2+1<=analysis_period,E2+1,"")) | G2: =IF(F2="","",IF(F2+1<=analysis_period,F2+1,"")) | H2: =IF(G2="","",IF(G2+1<=analysis_period,G2+1,"")) | I2: =IF(H2="","",IF(H2+1<=analysis_period,H2+1,"")) | J2: =IF(I2="","",IF(I2+1<=analysis_period,I2+1,"")) | ... AP2: =IF(AO2="","",IF(AO2+1<=analysis_period,AO2+1,""))
A4: Energy
A5: Electricity to grid (AC kWh) | B5: {=Inputs!C162:AQ163} -> 0 | C5: 0 | D5: 0 | E5: 0 | F5: 0 | G5: 0 | H5: 0 | I5: 0 | J5: 0 | K5: 0 | L5: 0 | M5: 0 | N5: 0 | O5: 0 | P5: 0 | Q5: 0 | R5: 0 | S5: 0 | T5: 0 | U5: 0 | V5: 0 | W5: 0 | X5: 0 | Y5: 0 | Z5: 0 | AA5: 0 | AB5: 0 | AC5: 0 | AD5: 0 | AE5: 0 | AF5: 0 | AG5: 0 | AH5: 0 | AI5: 0 | AJ5: 0 | AK5: 0 | AL5: 0 | AM5: 0 | AN5: 0 | AO5: 0 | AP5: 0
A6: Electricity from grid (AC kWh) | B6: 0 | C6: 0 | D6: 0 | E6: 0 | F6: 0 | G6: 0 | H6: 0 | I6: 0 | J6: 0 | K6: 0 | L6: 0 | M6: 0 | N6: 0 | O6: 0 | P6: 0 | Q6: 0 | R6: 0 | S6: 0 | T6: 0 | U6: 0 | V6: 0 | W6: 0 | X6: 0 | Y6: 0 | Z6: 0 | AA6: 0 | AB6: 0 | AC6: 0 | AD6: 0 | AE6: 0 | AF6: 0 | AG6: 0 | AH6: 0 | AI6: 0 | AJ6: 0 | AK6: 0 | AL6: 0 | AM6: 0 | AN6: 0 | AO6: 0 | AP6: 0
A7: Electricity to grid net (AC kWh) | B7: =SUM(B5:B6) -> 0 | C7: =SUM(C5:C6) -> 0 | D7: =SUM(D5:D6) -> 0 | E7: =SUM(E5:E6) -> 0 | F7: =SUM(F5:F6) -> 0 | G7: =SUM(G5:G6) -> 0 | H7: =SUM(H5:H6) -> 0 | I7: =SUM(I5:I6) -> 0 | ... AP7: =SUM(AP5:AP6) -> 0
A8: Electricity generated without storage (AC kWh) | B8: {=Inputs!C165:AQ167} -> 0 | C8: 0 | D8: 0 | E8: 0 | F8: 0 | G8: 0 | H8: 0 | I8: 0 | J8: 0 | K8: 0 | L8: 0 | M8: 0 | N8: 0 | O8: 0 | P8: 0 | Q8: 0 | R8: 0 | S8: 0 | T8: 0 | U8: 0 | V8: 0 | W8: 0 | X8: 0 | Y8: 0 | Z8: 0 | AA8: 0 | AB8: 0 | AC8: 0 | AD8: 0 | AE8: 0 | AF8: 0 | AG8: 0 | AH8: 0 | AI8: 0 | AJ8: 0 | AK8: 0 | AL8: 0 | AM8: 0 | AN8: 0 | AO8: 0 | AP8: 0
A9: Battery annual energy discharged (AC kWh) | B9: 0 | C9: 0 | D9: 0 | E9: 0 | F9: 0 | G9: 0 | H9: 0 | I9: 0 | J9: 0 | K9: 0 | L9: 0 | M9: 0 | N9: 0 | O9: 0 | P9: 0 | Q9: 0 | R9: 0 | S9: 0 | T9: 0 | U9: 0 | V9: 0 | W9: 0 | X9: 0 | Y9: 0 | Z9: 0 | AA9: 0 | AB9: 0 | AC9: 0 | AD9: 0 | AE9: 0 | AF9: 0 | AG9: 0 | AH9: 0 | AI9: 0 | AJ9: 0 | AK9: 0 | AL9: 0 | AM9: 0 | AN9: 0 | AO9: 0 | AP9: 0
A10: Fuel cell annual energy discharged (AC kWh) | B10: 0 | C10: 0 | D10: 0 | E10: 0 | F10: 0 | G10: 0 | H10: 0 | I10: 0 | J10: 0 | K10: 0 | L10: 0 | M10: 0 | N10: 0 | O10: 0 | P10: 0 | Q10: 0 | R10: 0 | S10: 0 | T10: 0 | U10: 0 | V10: 0 | W10: 0 | X10: 0 | Y10: 0 | Z10: 0 | AA10: 0 | AB10: 0 | AC10: 0 | AD10: 0 | AE10: 0 | AF10: 0 | AG10: 0 | AH10: 0 | AI10: 0 | AJ10: 0 | AK10: 0 | AL10: 0 | AM10: 0 | AN10: 0 | AO10: 0 | AP10: 0
A12: Partial Income Statement: Project
A13: Revenues
A14: PPA
A15: Net production (AC kWh) | C15: =C$5 -> 0 | D15: =D$5 -> 0 | E15: =E$5 -> 0 | F15: =F$5 -> 0 | G15: =G$5 -> 0 | H15: =H$5 -> 0 | I15: =I$5 -> 0 | J15: =J$5 -> 0 | ... AP15: =AP$5 -> 0
A16: Price (¢/kWh) | B16: {=Inputs!C169:AQ169} -> 0 | C16: 0 | D16: 0 | E16: 0 | F16: 0 | G16: 0 | H16: 0 | I16: 0 | J16: 0 | K16: 0 | L16: 0 | M16: 0 | N16: 0 | O16: 0 | P16: 0 | Q16: 0 | R16: 0 | S16: 0 | T16: 0 | U16: 0 | V16: 0 | W16: 0 | X16: 0 | Y16: 0 | Z16: 0 | AA16: 0 | AB16: 0 | AC16: 0 | AD16: 0 | AE16: 0 | AF16: 0 | AG16: 0 | AH16: 0 | AI16: 0 | AJ16: 0 | AK16: 0 | AL16: 0 | AM16: 0 | AN16: 0 | AO16: 0 | AP16: 0
A17: PPA revenue (TOD multipliers may apply) | B17: {=Inputs!C170:AQ170} -> 0 | C17: 0 | D17: 0 | E17: 0 | F17: 0 | G17: 0 | H17: 0 | I17: 0 | J17: 0 | K17: 0 | L17: 0 | M17: 0 | N17: 0 | O17: 0 | P17: 0 | Q17: 0 | R17: 0 | S17: 0 | T17: 0 | U17: 0 | V17: 0 | W17: 0 | X17: 0 | Y17: 0 | Z17: 0 | AA17: 0 | AB17: 0 | AC17: 0 | AD17: 0 | AE17: 0 | AF17: 0 | AG17: 0 | AH17: 0 | AI17: 0 | AJ17: 0 | AK17: 0 | AL17: 0 | AM17: 0 | AN17: 0 | AO17: 0 | AP17: 0
A18: Other revenue
A19: Curtailment payments | B19: {=Inputs!C171:AQ173} -> 0 | C19: 0 | D19: 0 | E19: 0 | F19: 0 | G19: 0 | H19: 0 | I19: 0 | J19: 0 | K19: 0 | L19: 0 | M19: 0 | N19: 0 | O19: 0 | P19: 0 | Q19: 0 | R19: 0 | S19: 0 | T19: 0 | U19: 0 | V19: 0 | W19: 0 | X19: 0 | Y19: 0 | Z19: 0 | AA19: 0 | AB19: 0 | AC19: 0 | AD19: 0 | AE19: 0 | AF19: 0 | AG19: 0 | AH19: 0 | AI19: 0 | AJ19: 0 | AK19: 0 | AL19: 0 | AM19: 0 | AN19: 0 | AO19: 0 | AP19: 0
A20: Capacity payments | B20: 0 | C20: 0 | D20: 0 | E20: 0 | F20: 0 | G20: 0 | H20: 0 | I20: 0 | J20: 0 | K20: 0 | L20: 0 | M20: 0 | N20: 0 | O20: 0 | P20: 0 | Q20: 0 | R20: 0 | S20: 0 | T20: 0 | U20: 0 | V20: 0 | W20: 0 | X20: 0 | Y20: 0 | Z20: 0 | AA20: 0 | AB20: 0 | AC20: 0 | AD20: 0 | AE20: 0 | AF20: 0 | AG20: 0 | AH20: 0 | AI20: 0 | AJ20: 0 | AK20: 0 | AL20: 0 | AM20: 0 | AN20: 0 | AO20: 0 | AP20: 0
A21: Thermal revenue (fuel cell only) | B21: 0 | C21: 0 | D21: 0 | E21: 0 | F21: 0 | G21: 0 | H21: 0 | I21: 0 | J21: 0 | K21: 0 | L21: 0 | M21: 0 | N21: 0 | O21: 0 | P21: 0 | Q21: 0 | R21: 0 | S21: 0 | T21: 0 | U21: 0 | V21: 0 | W21: 0 | X21: 0 | Y21: 0 | Z21: 0 | AA21: 0 | AB21: 0 | AC21: 0 | AD21: 0 | AE21: 0 | AF21: 0 | AG21: 0 | AH21: 0 | AI21: 0 | AJ21: 0 | AK21: 0 | AL21: 0 | AM21: 0 | AN21: 0 | AO21: 0 | AP21: 0
A22: Production Based Incentive (included if available for debt service)
A23: Federal | C23: =IF(pbi_fed_for_ds="Yes",C624,0) -> 0 | D23: =IF(pbi_fed_for_ds="Yes",D624,0) -> 0 | E23: =IF(pbi_fed_for_ds="Yes",E624,0) -> 0 | F23: =IF(pbi_fed_for_ds="Yes",F624,0) -> 0 | G23: =IF(pbi_fed_for_ds="Yes",G624,0) -> 0 | H23: =IF(pbi_fed_for_ds="Yes",H624,0) -> 0 | I23: =IF(pbi_fed_for_ds="Yes",I624,0) -> 0 | J23: =IF(pbi_fed_for_ds="Yes",J624,0) -> 0 | ... AP23: =IF(pbi_fed_for_ds="Yes",AP624,0) -> 0
A24: State | C24: =IF(pbi_sta_for_ds="Yes",C628,0) -> 0 | D24: =IF(pbi_sta_for_ds="Yes",D628,0) -> 0 | E24: =IF(pbi_sta_for_ds="Yes",E628,0) -> 0 | F24: =IF(pbi_sta_for_ds="Yes",F628,0) -> 0 | G24: =IF(pbi_sta_for_ds="Yes",G628,0) -> 0 | H24: =IF(pbi_sta_for_ds="Yes",H628,0) -> 0 | I24: =IF(pbi_sta_for_ds="Yes",I628,0) -> 0 | J24: =IF(pbi_sta_for_ds="Yes",J628,0) -> 0 | ... AP24: =IF(pbi_sta_for_ds="Yes",AP628,0) -> 0
A25: Utility | C25: =IF(pbi_uti_for_ds="Yes",C632,0) -> 0 | D25: =IF(pbi_uti_for_ds="Yes",D632,0) -> 0 | E25: =IF(pbi_uti_for_ds="Yes",E632,0) -> 0 | F25: =IF(pbi_uti_for_ds="Yes",F632,0) -> 0 | G25: =IF(pbi_uti_for_ds="Yes",G632,0) -> 0 | H25: =IF(pbi_uti_for_ds="Yes",H632,0) -> 0 | I25: =IF(pbi_uti_for_ds="Yes",I632,0) -> 0 | J25: =IF(pbi_uti_for_ds="Yes",J632,0) -> 0 | ... AP25: =IF(pbi_uti_for_ds="Yes",AP632,0) -> 0
A26: Other | C26: =IF(pbi_oth_for_ds="Yes",C636,0) -> 0 | D26: =IF(pbi_oth_for_ds="Yes",D636,0) -> 0 | E26: =IF(pbi_oth_for_ds="Yes",E636,0) -> 0 | F26: =IF(pbi_oth_for_ds="Yes",F636,0) -> 0 | G26: =IF(pbi_oth_for_ds="Yes",G636,0) -> 0 | H26: =IF(pbi_oth_for_ds="Yes",H636,0) -> 0 | I26: =IF(pbi_oth_for_ds="Yes",I636,0) -> 0 | J26: =IF(pbi_oth_for_ds="Yes",J636,0) -> 0 | ... AP26: =IF(pbi_oth_for_ds="Yes",AP636,0) -> 0
A27: Total PBI | C27: =SUM(C23:C26) -> 0 | D27: =SUM(D23:D26) -> 0 | E27: =SUM(E23:E26) -> 0 | F27: =SUM(F23:F26) -> 0 | G27: =SUM(G23:G26) -> 0 | H27: =SUM(H23:H26) -> 0 | I27: =SUM(I23:I26) -> 0 | J27: =SUM(J23:J26) -> 0 | ... AP27: =SUM(AP23:AP26) -> 0
A28: Salvage Value | C28: =IF(C2=analysis_period,total_installed_cost*salvage_percentage/100,0) -> 0 | D28: =IF(D2=analysis_period,total_installed_cost*salvage_percentage/100,0) -> 0 | E28: =IF(E2=analysis_period,total_installed_cost*salvage_percentage/100,0) -> 0 | F28: =IF(F2=analysis_period,total_installed_cost*salvage_percentage/100,0) -> 0 | G28: =IF(G2=analysis_period,total_installed_cost*salvage_percentage/100,0) -> 0 | H28: =IF(H2=analysis_period,total_installed_cost*salvage_percentage/100,0) -> 0 | I28: =IF(I2=analysis_period,total_installed_cost*salvage_percentage/100,0) -> 0 | J28: =IF(J2=analysis_period,total_installed_cost*salvage_percentage/100,0) -> 0 | ... AP28: =IF(AP2=analysis_period,total_installed_cost*salvage_percentage/100,0) -> 0
A29: Total Revenue | C29: =IF(C2<=analysis_period,C$17+SUM(C19:C21)+C$27+C$28,0) -> 0 | D29: =IF(D2<=analysis_period,D$17+SUM(D19:D21)+D$27+D$28,0) -> 0 | E29: =IF(E2<=analysis_period,E$17+SUM(E19:E21)+E$27+E$28,0) -> 0 | F29: =IF(F2<=analysis_period,F$17+SUM(F19:F21)+F$27+F$28,0) -> 0 | G29: =IF(G2<=analysis_period,G$17+SUM(G19:G21)+G$27+G$28,0) -> 0 | H29: =IF(H2<=analysis_period,H$17+SUM(H19:H21)+H$27+H$28,0) -> 0 | I29: =IF(I2<=analysis_period,I$17+SUM(I19:I21)+I$27+I$28,0) -> 0 | J29: =IF(J2<=analysis_period,J$17+SUM(J19:J21)+J$27+J$28,0) -> 0 | ... AP29: =IF(AP2<=analysis_period,AP$17+SUM(AP19:AP21)+AP$27+AP$28,0) -> 0
A31: Property tax net assessed value | C31: =PropertyTaxAssessedValue -> 0 | D31: =IF(D$2<=analysis_period,PropertyTaxAssessedValue*(100-(D$2-1)*prop_tax_assessed_decline)/100,0) -> 0 | E31: =IF(E$2<=analysis_period,PropertyTaxAssessedValue*(100-(E$2-1)*prop_tax_assessed_decline)/100,0) -> 0 | F31: =IF(F$2<=analysis_period,PropertyTaxAssessedValue*(100-(F$2-1)*prop_tax_assessed_decline)/100,0) -> 0 | G31: =IF(G$2<=analysis_period,PropertyTaxAssessedValue*(100-(G$2-1)*prop_tax_assessed_decline)/100,0) -> 0 | H31: =IF(H$2<=analysis_period,PropertyTaxAssessedValue*(100-(H$2-1)*prop_tax_assessed_decline)/100,0) -> 0 | I31: =IF(I$2<=analysis_period,PropertyTaxAssessedValue*(100-(I$2-1)*prop_tax_assessed_decline)/100,0) -> 0 | J31: =IF(J$2<=analysis_period,PropertyTaxAssessedValue*(100-(J$2-1)*prop_tax_assessed_decline)/100,0) -> 0 | K31: =IF(K$2<=analysis_period,PropertyTaxAssessedValue*(100-(K$2-1)*prop_tax_assessed_decline)/100,0) -> 0 | ... AP31: =IF(AP$2<=analysis_period,PropertyTaxAssessedValue*(100-(AP$2-1)*prop_tax_assessed_decline)/100,0) -> 0
A33: Operating Expenses
A34: Operation and maintenance (O&M)
A35: Fixed | C35: =IF(C$2<=analysis_period,IF(om_fixed="n/a",Inputs!D175,om_fixed*(1+inflation_rate/100+om_fixed_escal/100)^B$2),0) -> 0 | D35: =IF(D$2<=analysis_period,IF(om_fixed="n/a",Inputs!E175,om_fixed*(1+inflation_rate/100+om_fixed_escal/100)^C$2),0) -> 0 | E35: =IF(E$2<=analysis_period,IF(om_fixed="n/a",Inputs!F175,om_fixed*(1+inflation_rate/100+om_fixed_escal/100)^D$2),0) -> 0 | F35: =IF(F$2<=analysis_period,IF(om_fixed="n/a",Inputs!G175,om_fixed*(1+inflation_rate/100+om_fixed_escal/100)^E$2),0) -> 0 | G35: =IF(G$2<=analysis_period,IF(om_fixed="n/a",Inputs!H175,om_fixed*(1+inflation_rate/100+om_fixed_escal/100)^F$2),0) -> 0 | H35: =IF(H$2<=analysis_period,IF(om_fixed="n/a",Inputs!I175,om_fixed*(1+inflation_rate/100+om_fixed_escal/100)^G$2),0) -> 0 | I35: =IF(I$2<=analysis_period,IF(om_fixed="n/a",Inputs!J175,om_fixed*(1+inflation_rate/100+om_fixed_escal/100)^H$2),0) -> 0 | J35: =IF(J$2<=analysis_period,IF(om_fixed="n/a",Inputs!K175,om_fixed*(1+inflation_rate/100+om_fixed_escal/100)^I$2),0) -> 0 | ... AP35: =IF(AP$2<=analysis_period,IF(om_fixed="n/a",Inputs!AQ175,om_fixed*(1+inflation_rate/100+om_fixed_escal/100)^AO$2),0) -> 0
A36: Capacity
A37: Capacity (DC kW) | C37: =IF(C$2<=analysis_period,system_capacity,0) -> 0 | D37: =IF(D$2<=analysis_period,system_capacity,0) -> 0 | E37: =IF(E$2<=analysis_period,system_capacity,0) -> 0 | F37: =IF(F$2<=analysis_period,system_capacity,0) -> 0 | G37: =IF(G$2<=analysis_period,system_capacity,0) -> 0 | H37: =IF(H$2<=analysis_period,system_capacity,0) -> 0 | I37: =IF(I$2<=analysis_period,system_capacity,0) -> 0 | J37: =IF(J$2<=analysis_period,system_capacity,0) -> 0 | ... AP37: =IF(AP$2<=analysis_period,system_capacity,0) -> 0
A38: Fixed Cost ($/DC kW-yr) | C38: =IF(C$2<=analysis_period,IF(om_capacity="n/a",Inputs!D176,om_capacity*(1+inflation_rate/100+om_capacity_escal/100)^B$2),0) -> 0 | D38: =IF(D$2<=analysis_period,IF(om_capacity="n/a",Inputs!E176,om_capacity*(1+inflation_rate/100+om_capacity_escal/100)^C$2),0) -> 0 | E38: =IF(E$2<=analysis_period,IF(om_capacity="n/a",Inputs!F176,om_capacity*(1+inflation_rate/100+om_capacity_escal/100)^D$2),0) -> 0 | F38: =IF(F$2<=analysis_period,IF(om_capacity="n/a",Inputs!G176,om_capacity*(1+inflation_rate/100+om_capacity_escal/100)^E$2),0) -> 0 | G38: =IF(G$2<=analysis_period,IF(om_capacity="n/a",Inputs!H176,om_capacity*(1+inflation_rate/100+om_capacity_escal/100)^F$2),0) -> 0 | H38: =IF(H$2<=analysis_period,IF(om_capacity="n/a",Inputs!I176,om_capacity*(1+inflation_rate/100+om_capacity_escal/100)^G$2),0) -> 0 | I38: =IF(I$2<=analysis_period,IF(om_capacity="n/a",Inputs!J176,om_capacity*(1+inflation_rate/100+om_capacity_escal/100)^H$2),0) -> 0 | J38: =IF(J$2<=analysis_period,IF(om_capacity="n/a",Inputs!K176,om_capacity*(1+inflation_rate/100+om_capacity_escal/100)^I$2),0) -> 0 | ... AP38: =IF(AP$2<=analysis_period,IF(om_capacity="n/a",Inputs!AQ176,om_capacity*(1+inflation_rate/100+om_capacity_escal/100)^AO$2),0) -> 0
A39: O&M capacity-based expense | C39: =C37*C38 -> 0 | D39: =D37*D38 -> 0 | E39: =E37*E38 -> 0 | F39: =F37*F38 -> 0 | G39: =G37*G38 -> 0 | H39: =H37*H38 -> 0 | I39: =I37*I38 -> 0 | J39: =J37*J38 -> 0 | ... AP39: =AP37*AP38 -> 0
A40: Variable
A41: Generation (AC-MWh) | C41: =IF(C$8>0,C$8,C$5)/1000 -> 0 | D41: =IF(D$8>0,D$8,D$5)/1000 -> 0 | E41: =IF(E$8>0,E$8,E$5)/1000 -> 0 | F41: =IF(F$8>0,F$8,F$5)/1000 -> 0 | G41: =IF(G$8>0,G$8,G$5)/1000 -> 0 | H41: =IF(H$8>0,H$8,H$5)/1000 -> 0 | I41: =IF(I$8>0,I$8,I$5)/1000 -> 0 | J41: =IF(J$8>0,J$8,J$5)/1000 -> 0 | ... AP41: =IF(AP$8>0,AP$8,AP$5)/1000 -> 0
A42: Variable Cost ($/AC-MWh) | C42: =IF(C$2<=analysis_period,IF(om_production="n/a",Inputs!D177,om_production*(1+inflation_rate/100+om_production_escal/100)^B$2),0) -> 0 | D42: =IF(D$2<=analysis_period,IF(om_production="n/a",Inputs!E177,om_production*(1+inflation_rate/100+om_production_escal/100)^C$2),0) -> 0 | E42: =IF(E$2<=analysis_period,IF(om_production="n/a",Inputs!F177,om_production*(1+inflation_rate/100+om_production_escal/100)^D$2),0) -> 0 | F42: =IF(F$2<=analysis_period,IF(om_production="n/a",Inputs!G177,om_production*(1+inflation_rate/100+om_production_escal/100)^E$2),0) -> 0 | G42: =IF(G$2<=analysis_period,IF(om_production="n/a",Inputs!H177,om_production*(1+inflation_rate/100+om_production_escal/100)^F$2),0) -> 0 | H42: =IF(H$2<=analysis_period,IF(om_production="n/a",Inputs!I177,om_production*(1+inflation_rate/100+om_production_escal/100)^G$2),0) -> 0 | I42: =IF(I$2<=analysis_period,IF(om_production="n/a",Inputs!J177,om_production*(1+inflation_rate/100+om_production_escal/100)^H$2),0) -> 0 | J42: =IF(J$2<=analysis_period,IF(om_production="n/a",Inputs!K177,om_production*(1+inflation_rate/100+om_production_escal/100)^I$2),0) -> 0 | ... AP42: =IF(AP$2<=analysis_period,IF(om_production="n/a",Inputs!AQ177,om_production*(1+inflation_rate/100+om_production_escal/100)^AO$2),0) -> 0
A43: O&M production-based expense | C43: =C41*C42 -> 0 | D43: =D41*D42 -> 0 | E43: =E41*E42 -> 0 | F43: =F41*F42 -> 0 | G43: =G41*G42 -> 0 | H43: =H41*H42 -> 0 | I43: =I41*I42 -> 0 | J43: =J41*J42 -> 0 | ... AP43: =AP41*AP42 -> 0
A44: Electricity purchase (Systems with battery only) | C44: {=Inputs!D197:AQ197} -> 0 | D44: 0 | E44: 0 | F44: 0 | G44: 0 | H44: 0 | I44: 0 | J44: 0 | K44: 0 | L44: 0 | M44: 0 | N44: 0 | O44: 0 | P44: 0 | Q44: 0 | R44: 0 | S44: 0 | T44: 0 | U44: 0 | V44: 0 | W44: 0 | X44: 0 | Y44: 0 | Z44: 0 | AA44: 0 | AB44: 0 | AC44: 0 | AD44: 0 | AE44: 0 | AF44: 0 | AG44: 0 | AH44: 0 | AI44: 0 | AJ44: 0 | AK44: 0 | AL44: 0 | AM44: 0 | AN44: 0 | AO44: 0 | AP44: 0
...

Sheet Depreciation Schedules
A1: Depreciation Schedules (Half Year)
A2: Year | B2: 5-yr MACRS | C2: 15-yr MACRS | D2: 5-yr SL | E2: 15-yr SL | F2: 20-yr SL | G2: 39-yr SL
A3: 1 | B3: 20 | C3: 5 | D3: 10 | E3: 3.33 | F3: 2.5 | G3: =2.56410256410256*0.5 -> 1.2820513
A4: 2 | B4: 32 | C4: 9.5 | D4: 20 | E4: 6.67 | F4: 5 | G4: 2.5641026
A5: 3 | B5: 19.2 | C5: 8.55 | D5: 20 | E5: 6.67 | F5: 5 | G5: 2.5641026
A6: 4 | B6: 11.52 | C6: 7.7 | D6: 20 | E6: 6.67 | F6: 5 | G6: 2.5641026
A7: 5 | B7: 11.52 | C7: 6.93 | D7: 20 | E7: 6.67 | F7: 5 | G7: 2.5641026
A8: 6 | B8: 5.76 | C8: 6.23 | D8: 10 | E8: 6.67 | F8: 5 | G8: 2.5641026
A9: 7 | B9: 0 | C9: 5.9 | D9: 0 | E9: 6.67 | F9: 5 | G9: 2.5641026
A10: 8 | B10: 0 | C10: 5.9 | D10: 0 | E10: 6.67 | F10: 5 | G10: 2.5641026
A11: 9 | B11: 0 | C11: 5.91 | D11: 0 | E11: 6.67 | F11: 5 | G11: 2.5641026
A12: 10 | B12: 0 | C12: 5.9 | D12: 0 | E12: 6.67 | F12: 5 | G12: 2.5641026
A13: 11 | B13: 0 | C13: 5.91 | D13: 0 | E13: 6.67 | F13: 5 | G13: 2.5641026
A14: 12 | B14: 0 | C14: 5.9 | D14: 0 | E14: 6.66 | F14: 5 | G14: 2.5641026
A15: 13 | B15: 0 | C15: 5.91 | D15: 0 | E15: 6.67 | F15: 5 | G15: 2.5641026
... A41: 39 | B41: 0 | C41: 0 | D41: 0 | E41: 0 | F41: 0 | G41: 2.5641026
A42: 40 | B42: 0 | C42: 0 | D42: 0 | E42: 0 | F42: 0 | G42: =2.56410256410256*0.5 -> 1.2820513
A43: For additional information on depreciation schedules, see IRS publication 946.
A44: http://www.irs.gov/pub/irs-pdf/p946.pdf
A45: * Note custom schedule is defined on Inputs sheet around Row 180
