Workbook
Name analysis_period: #REF!
Name analysis_period: 'Inputs and Outputs'!$B$36
Name annual_fuel_usage: #REF!
Name annual_fuel_usage: 'Inputs and Outputs'!$B$18
Name AnnualOMCapacity: 'Inputs and Outputs'!$C$114
Name AnnualOMFixed: 'Inputs and Outputs'!$C$113
Name AnnualOMProduction: 'Inputs and Outputs'!$C$116
Name AnnualPBIFederal: 'Inputs and Outputs'!$C$146
Name AnnualPBIOther: 'Inputs and Outputs'!$C$149
Name AnnualPBIState: 'Inputs and Outputs'!$C$147
Name AnnualPBIUtility: 'Inputs and Outputs'!$C$148
Name AnnualPTCFederal: 'Inputs and Outputs'!$C$151
Name AnnualPTCState: 'Inputs and Outputs'!$C$152
Name AnnualTaxFederal: #REF!
Name AnnualTaxFederal: 'Inputs and Outputs'!$B$111
Name AnnualTaxState: #REF!
Name AnnualTaxState: 'Inputs and Outputs'!$B$110
Name batt_annual_discharge_energy: 'Inputs and Outputs'!$B$155
Name batt_computed_bank_capacity: 'Inputs and Outputs'!$B$119
Name batt_replacement_cost: 'Inputs and Outputs'!$B$121
Name batt_replacement_cost_escal: 'Inputs and Outputs'!$B$122
Name batt_replacement_option: 'Inputs and Outputs'!$B$120
Name BatteryReplSched: 'Inputs and Outputs'!$B$124
Name CashFlow: 'Cash Flow'!$C$134:$CX$134
Name cbi_fed_amount: #REF!
Name cbi_fed_amount: 'Inputs and Outputs'!$B$80
Name cbi_fed_deprbas_fed: #REF!
Name cbi_fed_deprbas_fed: 'Inputs and Outputs'!$F$80
Name cbi_fed_deprbas_sta: #REF!
Name cbi_fed_deprbas_sta: 'Inputs and Outputs'!$G$80
Name cbi_fed_maxvalue: #REF!
Name cbi_fed_maxvalue: 'Inputs and Outputs'!$C$80
Name cbi_fed_tax_fed: #REF!
Name cbi_fed_tax_fed: 'Inputs and Outputs'!$D$80
Name cbi_fed_tax_sta: #REF!
Name cbi_fed_tax_sta: 'Inputs and Outputs'!$E$80
Name cbi_oth_amount: #REF!
Name cbi_oth_amount: 'Inputs and Outputs'!$B$83
Name cbi_oth_deprbas_fed: #REF!
Name cbi_oth_deprbas_fed: 'Inputs and Outputs'!$F$83
Name cbi_oth_deprbas_sta: #REF!
Name cbi_oth_deprbas_sta: 'Inputs and Outputs'!$G$83
Name cbi_oth_maxvalue: #REF!
Name cbi_oth_maxvalue: 'Inputs and Outputs'!$C$83
Name cbi_oth_tax_fed: #REF!
Name cbi_oth_tax_fed: 'Inputs and Outputs'!$D$83
Name cbi_oth_tax_sta: #REF!
Name cbi_oth_tax_sta: 'Inputs and Outputs'!$E$83
Name cbi_sta_amount: #REF!
Name cbi_sta_amount: 'Inputs and Outputs'!$B$81
Name cbi_sta_deprbas_fed: #REF!
Name cbi_sta_deprbas_fed: 'Inputs and Outputs'!$F$81
Name cbi_sta_deprbas_sta: #REF!
Name cbi_sta_deprbas_sta: 'Inputs and Outputs'!$G$81
Name cbi_sta_maxvalue: #REF!
Name cbi_sta_maxvalue: 'Inputs and Outputs'!$C$81
Name cbi_sta_tax_fed: #REF!
Name cbi_sta_tax_fed: 'Inputs and Outputs'!$D$81
Name cbi_sta_tax_sta: #REF!
Name cbi_sta_tax_sta: 'Inputs and Outputs'!$E$81

Sheet Inputs and Outputs
A1: Residential and Commercial Inputs | D1: KEY
A2: SYSTEM DESIGN | D2: Calculated
A3: Nameplate capacity (kW) | B3: 0 | D3: Input from SAM
A4: Year 1 net energy (kWh/year) | B4: 0 | D4: Annual values from SAM
A6: SYSTEM COSTS | D6: RESULTS
A7: Total Installed Cost ($) | B7: 0 | D7: LCOE (real) ¢/kWh | E7: =(-'Cash Flow'!B132-NPV(NominalDiscountRate/100,'Cash Flow'!C132:CX132))/NPV(real_discount_rate/100,'Cash Flow'!C5:CX5)*100 -> #DIV/0!
A8: Operation and Maintenance (O&M) | D8: LCOE (nominal), ¢/kWh | E8: =(-'Cash Flow'!B132-NPV(NominalDiscountRate/100,'Cash Flow'!C132:CX132))/NPV(NominalDiscountRate/100,'Cash Flow'!C5:CX5)*100 -> #DIV/0!
A9: Fixed (Annual) O&M ($/yr) | B9: 0 | D9: NPV | E9: ='Cash Flow'!B134+NPV(NominalDiscountRate/100,'Cash Flow'!C134:CX134) -> 0
A10: Escalation rate (%/year) | B10: 0 | D10: Payback period, years | E10: =IF('Cash Flow'!C142>analysis_period,"> analysis period",'Cash Flow'!C142) -> > analysis period
A11: Fixed O&M ($/kW-yr) | B11: 0 | D11: Discounted payback,yrs | E11: =IF('Cash Flow'!C148>analysis_period,"> analysis period",'Cash Flow'!C148) -> > analysis period
A12: Escalation rate (%/year) | B12: 0
A13: Variable O&M ($/MWh) | B13: 0
A14: Escalation rate (%/year) | B14: 0
A15: Battery replacements | B15: =IF(batt_replacement_option=0,"None",IF(batt_replacement_option=1,"Calculated","See Ann. Val. below")) -> None
A16: Fuel
A17: CSP, generic system
A18: Annual fuel usage (kWh) | B18: 0
A19: Heat rate, generic only (MMBTU/MWh) | B19: 0
A20: Fuel cost ($/MMBtu) | B20: 0
A21: Escalation rate (%/year) | B21: 0
A22: Biomass power
A23: Annual biomass feedstock usage (dry ton) | B23: 0
A24: Biomass feedstock cost ($/dry ton) | B24: 0
A25: Escalation rate (%/year) | B25: 0
A26: Coal feedstock usage (dry ton) | B26: 0
A27: Coal feedstock cost ($/dry ton) | B27: 0
A28: Escalation rate (%/year) | B28: 0
A30: LOAN PARAMETERS
A31: Debt fraction (% of total installed cost) | B31: 0
A32: Loan term (years) | B32: 0
A33: Loan rate (%/year) | B33: 0
A35: ANALYSIS PARAMETERS
A36: Analysis period (years) | B36: 0
A37: Inflation rate (%/year) | B37: 0
A38: Real discount rate (%/year) | B38: 0
A39: Nominal discount rate (%/year) | B39: =((inflation_rate/100+1)*(real_discount_rate/100+1)-1)*100 -> 0
A41: TAX AND INSURANCE RATES
A42: Federal income tax rate in Year 1(%) | B42: =AnnualTaxFederal -> 0
A43: State income tax rate in Year 1 (%) | B43: =AnnualTaxState -> 0
A44: Sales tax (% of direct costs) | B44: 0
...

Sheet Cash Flow
A1: Residential and Commercial Cash Flow
A2: Operating Year | B2: 0 | C2: =IF(( (COLUMN(C1) - COLUMN($B1)) <= analysis_period), (COLUMN(C1) - COLUMN($B1)), "") | D2: =IF(( (COLUMN(D1) - COLUMN($B1)) <= analysis_period), (COLUMN(D1) - COLUMN($B1)), "") | E2: =IF(( (COLUMN(E1) - COLUMN($B1)) <= analysis_period), (COLUMN(E1) - COLUMN($B1)), "") | F2: =IF(( (COLUMN(F1) - COLUMN($B1)) <= analysis_period), (COLUMN(F1) - COLUMN($B1)), "") | G2: =IF(( (COLUMN(G1) - COLUMN($B1)) <= analysis_period), (COLUMN(G1) - COLUMN($B1)), "") | H2: =IF(( (COLUMN(H1) - COLUMN($B1)) <= analysis_period), (COLUMN(H1) - COLUMN($B1)), "") | I2: =IF(( (COLUMN(I1) - COLUMN($B1)) <= analysis_period), (COLUMN(I1) - COLUMN($B1)), "") | J2: =IF(( (COLUMN(J1) - COLUMN($B1)) <= analysis_period), (COLUMN(J1) - COLUMN($B1)), "") | ... CX2: =IF(( (COLUMN(CX1) - COLUMN($B1)) <= analysis_period), (COLUMN(CX1) - COLUMN($B1)), "")
A4: Production
A5: Annual energy (AC kWh) | B5: {='Inputs and Outputs'!B105:CX105} -> 0 | C5: 0 | D5: 0 | E5: 0 | F5: 0 | G5: 0 | H5: 0 | I5: 0 | J5: 0 | K5: 0 | L5: 0 | M5: 0 | N5: 0 | O5: 0 | P5: 0 | Q5: 0 | R5: 0 | S5: 0 | T5: 0 | U5: 0 | V5: 0 | W5: 0 | X5: 0 | Y5: 0 | Z5: 0 | AA5: 0 | AB5: 0 | AC5: 0 | AD5: 0 | AE5: 0 | AF5: 0 | AG5: 0 | AH5: 0 | AI5: 0 | AJ5: 0 | AK5: 0 | AL5: 0 | AM5: 0 | AN5: 0 | AO5: 0 | AP5: 0 | AQ5: 0 | AR5: 0 | AS5: 0 | AT5: 0 | AU5: 0 | AV5: 0 | AW5: 0 | AX5: 0 | AY5: 0 | AZ5: 0 | BA5: 0 | BB5: 0 | BC5: 0 | BD5: 0 | BE5: 0 | BF5: 0 | BG5: 0 | BH5: 0 | BI5: 0 | BJ5: 0 | BK5: 0 | BL5: 0 | BM5: 0 | BN5: 0 | BO5: 0 | BP5: 0 | BQ5: 0 | BR5: 0 | BS5: 0 | BT5: 0 | BU5: 0 | BV5: 0 | BW5: 0 | BX5: 0 | BY5: 0 | BZ5: 0 | CA5: 0 | CB5: 0 | CC5: 0 | CD5: 0 | CE5: 0 | CF5: 0 | CG5: 0 | CH5: 0 | CI5: 0 | CJ5: 0 | CK5: 0 | CL5: 0 | CM5: 0 | CN5: 0 | CO5: 0 | CP5: 0 | CQ5: 0 | CR5: 0 | CS5: 0 | CT5: 0 | CU5: 0 | CV5: 0 | CW5: 0 | CX5: 0
A6: Energy generated without battery or curtailment (kWh) | B6: {='Inputs and Outputs'!B107:CX107} -> 0 | C6: 0 | D6: 0 | E6: 0 | F6: 0 | G6: 0 | H6: 0 | I6: 0 | J6: 0 | K6: 0 | L6: 0 | M6: 0 | N6: 0 | O6: 0 | P6: 0 | Q6: 0 | R6: 0 | S6: 0 | T6: 0 | U6: 0 | V6: 0 | W6: 0 | X6: 0 | Y6: 0 | Z6: 0 | AA6: 0 | AB6: 0 | AC6: 0 | AD6: 0 | AE6: 0 | AF6: 0 | AG6: 0 | AH6: 0 | AI6: 0 | AJ6: 0 | AK6: 0 | AL6: 0 | AM6: 0 | AN6: 0 | AO6: 0 | AP6: 0 | AQ6: 0 | AR6: 0 | AS6: 0 | AT6: 0 | AU6: 0 | AV6: 0 | AW6: 0 | AX6: 0 | AY6: 0 | AZ6: 0 | BA6: 0 | BB6: 0 | BC6: 0 | BD6: 0 | BE6: 0 | BF6: 0 | BG6: 0 | BH6: 0 | BI6: 0 | BJ6: 0 | BK6: 0 | BL6: 0 | BM6: 0 | BN6: 0 | BO6: 0 | BP6: 0 | BQ6: 0 | BR6: 0 | BS6: 0 | BT6: 0 | BU6: 0 | BV6: 0 | BW6: 0 | BX6: 0 | BY6: 0 | BZ6: 0 | CA6: 0 | CB6: 0 | CC6: 0 | CD6: 0 | CE6: 0 | CF6: 0 | CG6: 0 | CH6: 0 | CI6: 0 | CJ6: 0 | CK6: 0 | CL6: 0 | CM6: 0 | CN6: 0 | CO6: 0 | CP6: 0 | CQ6: 0 | CR6: 0 | CS6: 0 | CT6: 0 | CU6: 0 | CV6: 0 | CW6: 0 | CX6: 0
A7: Battery annual energy discharged (kWh) | B7: {='Inputs and Outputs'!B108:CX108} -> 0 | C7: 0 | D7: 0 | E7: 0 | F7: 0 | G7: 0 | H7: 0 | I7: 0 | J7: 0 | K7: 0 | L7: 0 | M7: 0 | N7: 0 | O7: 0 | P7: 0 | Q7: 0 | R7: 0 | S7: 0 | T7: 0 | U7: 0 | V7: 0 | W7: 0 | X7: 0 | Y7: 0 | Z7: 0 | AA7: 0 | AB7: 0 | AC7: 0 | AD7: 0 | AE7: 0 | AF7: 0 | AG7: 0 | AH7: 0 | AI7: 0 | AJ7: 0 | AK7: 0 | AL7: 0 | AM7: 0 | AN7: 0 | AO7: 0 | AP7: 0 | AQ7: 0 | AR7: 0 | AS7: 0 | AT7: 0 | AU7: 0 | AV7: 0 | AW7: 0 | AX7: 0 | AY7: 0 | AZ7: 0 | BA7: 0 | BB7: 0 | BC7: 0 | BD7: 0 | BE7: 0 | BF7: 0 | BG7: 0 | BH7: 0 | BI7: 0 | BJ7: 0 | BK7: 0 | BL7: 0 | BM7: 0 | BN7: 0 | BO7: 0 | BP7: 0 | BQ7: 0 | BR7: 0 | BS7: 0 | BT7: 0 | BU7: 0 | BV7: 0 | BW7: 0 | BX7: 0 | BY7: 0 | BZ7: 0 | CA7: 0 | CB7: 0 | CC7: 0 | CD7: 0 | CE7: 0 | CF7: 0 | CG7: 0 | CH7: 0 | CI7: 0 | CJ7: 0 | CK7: 0 | CL7: 0 | CM7: 0 | CN7: 0 | CO7: 0 | CP7: 0 | CQ7: 0 | CR7: 0 | CS7: 0 | CT7: 0 | CU7: 0 | CV7: 0 | CW7: 0 | CX7: 0
A8: Fuel cell annual energy discharged (kWh) | B8: {='Inputs and Outputs'!B157:CX157} -> 0 | C8: 0 | D8: 0 | E8: 0 | F8: 0 | G8: 0 | H8: 0 | I8: 0 | J8: 0 | K8: 0 | L8: 0 | M8: 0 | N8: 0 | O8: 0 | P8: 0 | Q8: 0 | R8: 0 | S8: 0 | T8: 0 | U8: 0 | V8: 0 | W8: 0 | X8: 0 | Y8: 0 | Z8: 0 | AA8: 0 | AB8: 0 | AC8: 0 | AD8: 0 | AE8: 0 | AF8: 0 | AG8: 0 | AH8: 0 | AI8: 0 | AJ8: 0 | AK8: 0 | AL8: 0 | AM8: 0 | AN8: 0 | AO8: 0 | AP8: 0 | AQ8: 0 | AR8: 0 | AS8: 0 | AT8: 0 | AU8: 0 | AV8: 0 | AW8: 0 | AX8: 0 | AY8: 0 | AZ8: 0 | BA8: 0 | BB8: 0 | BC8: 0 | BD8: 0 | BE8: 0 | BF8: 0 | BG8: 0 | BH8: 0 | BI8: 0 | BJ8: 0 | BK8: 0 | BL8: 0 | BM8: 0 | BN8: 0 | BO8: 0 | BP8: 0 | BQ8: 0 | BR8: 0 | BS8: 0 | BT8: 0 | BU8: 0 | BV8: 0 | BW8: 0 | BX8: 0 | BY8: 0 | BZ8: 0 | CA8: 0 | CB8: 0 | CC8: 0 | CD8: 0 | CE8: 0 | CF8: 0 | CG8: 0 | CH8: 0 | CI8: 0 | CJ8: 0 | CK8: 0 | CL8: 0 | CM8: 0 | CN8: 0 | CO8: 0 | CP8: 0 | CQ8: 0 | CR8: 0 | CS8: 0 | CT8: 0 | CU8: 0 | CV8: 0 | CW8: 0 | CX8: 0
A10: Savings
A11: Value of electricity savings ($) | B11: {='Inputs and Outputs'!B107:CX107} -> 0 | C11: 0 | D11: 0 | E11: 0 | F11: 0 | G11: 0 | H11: 0 | I11: 0 | J11: 0 | K11: 0 | L11: 0 | M11: 0 | N11: 0 | O11: 0 | P11: 0 | Q11: 0 | R11: 0 | S11: 0 | T11: 0 | U11: 0 | V11: 0 | W11: 0 | X11: 0 | Y11: 0 | Z11: 0 | AA11: 0 | AB11: 0 | AC11: 0 | AD11: 0 | AE11: 0 | AF11: 0 | AG11: 0 | AH11: 0 | AI11: 0 | AJ11: 0 | AK11: 0 | AL11: 0 | AM11: 0 | AN11: 0 | AO11: 0 | AP11: 0 | AQ11: 0 | AR11: 0 | AS11: 0 | AT11: 0 | AU11: 0 | AV11: 0 | AW11: 0 | AX11: 0 | AY11: 0 | AZ11: 0 | BA11: 0 | BB11: 0 | BC11: 0 | BD11: 0 | BE11: 0 | BF11: 0 | BG11: 0 | BH11: 0 | BI11: 0 | BJ11: 0 | BK11: 0 | BL11: 0 | BM11: 0 | BN11: 0 | BO11: 0 | BP11: 0 | BQ11: 0 | BR11: 0 | BS11: 0 | BT11: 0 | BU11: 0 | BV11: 0 | BW11: 0 | BX11: 0 | BY11: 0 | BZ11: 0 | CA11: 0 | CB11: 0 | CC11: 0 | CD11: 0 | CE11: 0 | CF11: 0 | CG11: 0 | CH11: 0 | CI11: 0 | CJ11: 0 | CK11: 0 | CL11: 0 | CM11: 0 | CN11: 0 | CO11: 0 | CP11: 0 | CQ11: 0 | CR11: 0 | CS11: 0 | CT11: 0 | CU11: 0 | CV11: 0 | CW11: 0 | CX11: 0
A12: Value of thermal energy savings (fuel cell only) ($) | B12: {='Inputs and Outputs'!B108:CX108} -> 0 | C12: 0 | D12: 0 | E12: 0 | F12: 0 | G12: 0 | H12: 0 | I12: 0 | J12: 0 | K12: 0 | L12: 0 | M12: 0 | N12: 0 | O12: 0 | P12: 0 | Q12: 0 | R12: 0 | S12: 0 | T12: 0 | U12: 0 | V12: 0 | W12: 0 | X12: 0 | Y12: 0 | Z12: 0 | AA12: 0 | AB12: 0 | AC12: 0 | AD12: 0 | AE12: 0 | AF12: 0 | AG12: 0 | AH12: 0 | AI12: 0 | AJ12: 0 | AK12: 0 | AL12: 0 | AM12: 0 | AN12: 0 | AO12: 0 | AP12: 0 | AQ12: 0 | AR12: 0 | AS12: 0 | AT12: 0 | AU12: 0 | AV12: 0 | AW12: 0 | AX12: 0 | AY12: 0 | AZ12: 0 | BA12: 0 | BB12: 0 | BC12: 0 | BD12: 0 | BE12: 0 | BF12: 0 | BG12: 0 | BH12: 0 | BI12: 0 | BJ12: 0 | BK12: 0 | BL12: 0 | BM12: 0 | BN12: 0 | BO12: 0 | BP12: 0 | BQ12: 0 | BR12: 0 | BS12: 0 | BT12: 0 | BU12: 0 | BV12: 0 | BW12: 0 | BX12: 0 | BY12: 0 | BZ12: 0 | CA12: 0 | CB12: 0 | CC12: 0 | CD12: 0 | CE12: 0 | CF12: 0 | CG12: 0 | CH12: 0 | CI12: 0 | CJ12: 0 | CK12: 0 | CL12: 0 | CM12: 0 | CN12: 0 | CO12: 0 | CP12: 0 | CQ12: 0 | CR12: 0 | CS12: 0 | CT12: 0 | CU12: 0 | CV12: 0 | CW12: 0 | CX12: 0
A14: Operating Expenses
A15: Operation and Maintenance (O&M)
A16: Fixed annual cost in $ | C16: =IF(AND(ISNUMBER(outYear),ISNUMBER(om_fixed)),om_fixed*(1+inflation_rate/100+om_fixed_escal/100)^B2,"") | D16: =IF(AND(ISNUMBER(outYear),ISNUMBER(om_fixed)),om_fixed*(1+inflation_rate/100+om_fixed_escal/100)^C2,"") | E16: =IF(AND(ISNUMBER(outYear),ISNUMBER(om_fixed)),om_fixed*(1+inflation_rate/100+om_fixed_escal/100)^D2,"") | F16: =IF(AND(ISNUMBER(outYear),ISNUMBER(om_fixed)),om_fixed*(1+inflation_rate/100+om_fixed_escal/100)^E2,"") | G16: =IF(AND(ISNUMBER(outYear),ISNUMBER(om_fixed)),om_fixed*(1+inflation_rate/100+om_fixed_escal/100)^F2,"") | H16: =IF(AND(ISNUMBER(outYear),ISNUMBER(om_fixed)),om_fixed*(1+inflation_rate/100+om_fixed_escal/100)^G2,"") | I16: =IF(AND(ISNUMBER(outYear),ISNUMBER(om_fixed)),om_fixed*(1+inflation_rate/100+om_fixed_escal/100)^H2,"") | J16: =IF(AND(ISNUMBER(outYear),ISNUMBER(om_fixed)),om_fixed*(1+inflation_rate/100+om_fixed_escal/100)^I2,"") | ... CX16: =IF(AND(ISNUMBER(outYear),ISNUMBER(om_fixed)),om_fixed*(1+inflation_rate/100+om_fixed_escal/100)^CW2,"")
A17: Or from annual schedule | C17: {='Inputs and Outputs'!C113:CX113} -> 0 | D17: 0 | E17: 0 | F17: 0 | G17: 0 | H17: 0 | I17: 0 | J17: 0 | K17: 0 | L17: 0 | M17: 0 | N17: 0 | O17: 0 | P17: 0 | Q17: 0 | R17: 0 | S17: 0 | T17: 0 | U17: 0 | V17: 0 | W17: 0 | X17: 0 | Y17: 0 | Z17: 0 | AA17: 0 | AB17: 0 | AC17: 0 | AD17: 0 | AE17: 0 | AF17: 0 | AG17: 0 | AH17: 0 | AI17: 0 | AJ17: 0 | AK17: 0 | AL17: 0 | AM17: 0 | AN17: 0 | AO17: 0 | AP17: 0 | AQ17: 0 | AR17: 0 | AS17: 0 | AT17: 0 | AU17: 0 | AV17: 0 | AW17: 0 | AX17: 0 | AY17: 0 | AZ17: 0 | BA17: 0 | BB17: 0 | BC17: 0 | BD17: 0 | BE17: 0 | BF17: 0 | BG17: 0 | BH17: 0 | BI17: 0 | BJ17: 0 | BK17: 0 | BL17: 0 | BM17: 0 | BN17: 0 | BO17: 0 | BP17: 0 | BQ17: 0 | BR17: 0 | BS17: 0 | BT17: 0 | BU17: 0 | BV17: 0 | BW17: 0 | BX17: 0 | BY17: 0 | BZ17: 0 | CA17: 0 | CB17: 0 | CC17: 0 | CD17: 0 | CE17: 0 | CF17: 0 | CG17: 0 | CH17: 0 | CI17: 0 | CJ17: 0 | CK17: 0 | CL17: 0 | CM17: 0 | CN17: 0 | CO17: 0 | CP17: 0 | CQ17: 0 | CR17: 0 | CS17: 0 | CT17: 0 | CU17: 0 | CV17: 0 | CW17: 0 | CX17: 0
A18: Capacity cost in $/kW | C18: =IF(AND(ISNUMBER(outYear),ISNUMBER(om_capacity)),om_capacity*(1+inflation_rate/100+om_capacity_escal/100)^B2*system_capacity,"") | D18: =IF(AND(ISNUMBER(outYear),ISNUMBER(om_capacity)),om_capacity*(1+inflation_rate/100+om_capacity_escal/100)^C2*system_capacity,"") | E18: =IF(AND(ISNUMBER(outYear),ISNUMBER(om_capacity)),om_capacity*(1+inflation_rate/100+om_capacity_escal/100)^D2*system_capacity,"") | F18: =IF(AND(ISNUMBER(outYear),ISNUMBER(om_capacity)),om_capacity*(1+inflation_rate/100+om_capacity_escal/100)^E2*system_capacity,"") | G18: =IF(AND(ISNUMBER(outYear),ISNUMBER(om_capacity)),om_capacity*(1+inflation_rate/100+om_capacity_escal/100)^F2*system_capacity,"") | H18: =IF(AND(ISNUMBER(outYear),ISNUMBER(om_capacity)),om_capacity*(1+inflation_rate/100+om_capacity_escal/100)^G2*system_capacity,"") | I18: =IF(AND(ISNUMBER(outYear),ISNUMBER(om_capacity)),om_capacity*(1+inflation_rate/100+om_capacity_escal/100)^H2*system_capacity,"") | J18: =IF(AND(ISNUMBER(outYear),ISNUMBER(om_capacity)),om_capacity*(1+inflation_rate/100+om_capacity_escal/100)^I2*system_capacity,"") | ... CX18: =IF(AND(ISNUMBER(outYear),ISNUMBER(om_capacity)),om_capacity*(1+inflation_rate/100+om_capacity_escal/100)^CW2*system_capacity,"")
A19: Or from annual schedule | C19: {='Inputs and Outputs'!C115:CX115} -> 0 | D19: 0 | E19: 0 | F19: 0 | G19: 0 | H19: 0 | I19: 0 | J19: 0 | K19: 0 | L19: 0 | M19: 0 | N19: 0 | O19: 0 | P19: 0 | Q19: 0 | R19: 0 | S19: 0 | T19: 0 | U19: 0 | V19: 0 | W19: 0 | X19: 0 | Y19: 0 | Z19: 0 | AA19: 0 | AB19: 0 | AC19: 0 | AD19: 0 | AE19: 0 | AF19: 0 | AG19: 0 | AH19: 0 | AI19: 0 | AJ19: 0 | AK19: 0 | AL19: 0 | AM19: 0 | AN19: 0 | AO19: 0 | AP19: 0 | AQ19: 0 | AR19: 0 | AS19: 0 | AT19: 0 | AU19: 0 | AV19: 0 | AW19: 0 | AX19: 0 | AY19: 0 | AZ19: 0 | BA19: 0 | BB19: 0 | BC19: 0 | BD19: 0 | BE19: 0 | BF19: 0 | BG19: 0 | BH19: 0 | BI19: 0 | BJ19: 0 | BK19: 0 | BL19: 0 | BM19: 0 | BN19: 0 | BO19: 0 | BP19: 0 | BQ19: 0 | BR19: 0 | BS19: 0 | BT19: 0 | BU19: 0 | BV19: 0 | BW19: 0 | BX19: 0 | BY19: 0 | BZ19: 0 | CA19: 0 | CB19: 0 | CC19: 0 | CD19: 0 | CE19: 0 | CF19: 0 | CG19: 0 | CH19: 0 | CI19: 0 | CJ19: 0 | CK19: 0 | CL19: 0 | CM19: 0 | CN19: 0 | CO19: 0 | CP19: 0 | CQ19: 0 | CR19: 0 | CS19: 0 | CT19: 0 | CU19: 0 | CV19: 0 | CW19: 0 | CX19: 0
A20: Variable cost in $/MWh | C20: =IF(AND(ISNUMBER(outYear),ISNUMBER(om_production)),om_production*(C5/1000)*(1+inflation_rate/100+om_production_escal/100)^B2,"") | D20: =IF(AND(ISNUMBER(outYear),ISNUMBER(om_production)),om_production*(D5/1000)*(1+inflation_rate/100+om_production_escal/100)^C2,"") | E20: =IF(AND(ISNUMBER(outYear),ISNUMBER(om_production)),om_production*(E5/1000)*(1+inflation_rate/100+om_production_escal/100)^D2,"") | F20: =IF(AND(ISNUMBER(outYear),ISNUMBER(om_production)),om_production*(F5/1000)*(1+inflation_rate/100+om_production_escal/100)^E2,"") | G20: =IF(AND(ISNUMBER(outYear),ISNUMBER(om_production)),om_production*(G5/1000)*(1+inflation_rate/100+om_production_escal/100)^F2,"") | H20: =IF(AND(ISNUMBER(outYear),ISNUMBER(om_production)),om_production*(H5/1000)*(1+inflation_rate/100+om_production_escal/100)^G2,"") | I20: =IF(AND(ISNUMBER(outYear),ISNUMBER(om_production)),om_production*(I5/1000)*(1+inflation_rate/100+om_production_escal/100)^H2,"") | J20: =IF(AND(ISNUMBER(outYear),ISNUMBER(om_production)),om_production*(J5/1000)*(1+inflation_rate/100+om_production_escal/100)^I2,"") | ... CX20: =IF(AND(ISNUMBER(outYear),ISNUMBER(om_production)),om_production*(CX5/1000)*(1+inflation_rate/100+om_production_escal/100)^CW2,"")
A21: Or from annual schedule | C21: {='Inputs and Outputs'!C117:CX117} -> 0 | D21: 0 | E21: 0 | F21: 0 | G21: 0 | H21: 0 | I21: 0 | J21: 0 | K21: 0 | L21: 0 | M21: 0 | N21: 0 | O21: 0 | P21: 0 | Q21: 0 | R21: 0 | S21: 0 | T21: 0 | U21: 0 | V21: 0 | W21: 0 | X21: 0 | Y21: 0 | Z21: 0 | AA21: 0 | AB21: 0 | AC21: 0 | AD21: 0 | AE21: 0 | AF21: 0 | AG21: 0 | AH21: 0 | AI21: 0 | AJ21: 0 | AK21: 0 | AL21: 0 | AM21: 0 | AN21: 0 | AO21: 0 | AP21: 0 | AQ21: 0 | AR21: 0 | AS21: 0 | AT21: 0 | AU21: 0 | AV21: 0 | AW21: 0 | AX21: 0 | AY21: 0 | AZ21: 0 | BA21: 0 | BB21: 0 | BC21: 0 | BD21: 0 | BE21: 0 | BF21: 0 | BG21: 0 | BH21: 0 | BI21: 0 | BJ21: 0 | BK21: 0 | BL21: 0 | BM21: 0 | BN21: 0 | BO21: 0 | BP21: 0 | BQ21: 0 | BR21: 0 | BS21: 0 | BT21: 0 | BU21: 0 | BV21: 0 | BW21: 0 | BX21: 0 | BY21: 0 | BZ21: 0 | CA21: 0 | CB21: 0 | CC21: 0 | CD21: 0 | CE21: 0 | CF21: 0 | CG21: 0 | CH21: 0 | CI21: 0 | CJ21: 0 | CK21: 0 | CL21: 0 | CM21: 0 | CN21: 0 | CO21: 0 | CP21: 0 | CQ21: 0 | CR21: 0 | CS21: 0 | CT21: 0 | CU21: 0 | CV21: 0 | CW21: 0 | CX21: 0
A22: Battery replacement | B22: {='Inputs and Outputs'!B127:CX127} -> 0 | C22: 0 | D22: 0 | E22: 0 | F22: 0 | G22: 0 | H22: 0 | I22: 0 | J22: 0 | K22: 0 | L22: 0 | M22: 0 | N22: 0 | O22: 0 | P22: 0 | Q22: 0 | R22: 0 | S22: 0 | T22: 0 | U22: 0 | V22: 0 | W22: 0 | X22: 0 | Y22: 0 | Z22: 0 | AA22: 0 | AB22: 0 | AC22: 0 | AD22: 0 | AE22: 0 | AF22: 0 | AG22: 0 | AH22: 0 | AI22: 0 | AJ22: 0 | AK22: 0 | AL22: 0 | AM22: 0 | AN22: 0 | AO22: 0 | AP22: 0 | AQ22: 0 | AR22: 0 | AS22: 0 | AT22: 0 | AU22: 0 | AV22: 0 | AW22: 0 | AX22: 0 | AY22: 0 | AZ22: 0 | BA22: 0 | BB22: 0 | BC22: 0 | BD22: 0 | BE22: 0 | BF22: 0 | BG22: 0 | BH22: 0 | BI22: 0 | BJ22: 0 | BK22: 0 | BL22: 0 | BM22: 0 | BN22: 0 | BO22: 0 | BP22: 0 | BQ22: 0 | BR22: 0 | BS22: 0 | BT22: 0 | BU22: 0 | BV22: 0 | BW22: 0 | BX22: 0 | BY22: 0 | BZ22: 0 | CA22: 0 | CB22: 0 | CC22: 0 | CD22: 0 | CE22: 0 | CF22: 0 | CG22: 0 | CH22: 0 | CI22: 0 | CJ22: 0 | CK22: 0 | CL22: 0 | CM22: 0 | CN22: 0 | CO22: 0 | CP22: 0 | CQ22: 0 | CR22: 0 | CS22: 0 | CT22: 0 | CU22: 0 | CV22: 0 | CW22: 0 | CX22: 0
A23: Battery operating costs
A24: Fixed | B24: {='Inputs and Outputs'!B129:CX129} -> 0 | C24: 0 | D24: 0 | E24: 0 | F24: 0 | G24: 0 | H24: 0 | I24: 0 | J24: 0 | K24: 0 | L24: 0 | M24: 0 | N24: 0 | O24: 0 | P24: 0 | Q24: 0 | R24: 0 | S24: 0 | T24: 0 | U24: 0 | V24: 0 | W24: 0 | X24: 0 | Y24: 0 | Z24: 0 | AA24: 0 | AB24: 0 | AC24: 0 | AD24: 0 | AE24: 0 | AF24: 0 | AG24: 0 | AH24: 0 | AI24: 0 | AJ24: 0 | AK24: 0 | AL24: 0 | AM24: 0 | AN24: 0 | AO24: 0 | AP24: 0 | AQ24: 0 | AR24: 0 | AS24: 0 | AT24: 0 | AU24: 0 | AV24: 0 | AW24: 0 | AX24: 0 | AY24: 0 | AZ24: 0 | BA24: 0 | BB24: 0 | BC24: 0 | BD24: 0 | BE24: 0 | BF24: 0 | BG24: 0 | BH24: 0 | BI24: 0 | BJ24: 0 | BK24: 0 | BL24: 0 | BM24: 0 | BN24: 0 | BO24: 0 | BP24: 0 | BQ24: 0 | BR24: 0 | BS24: 0 | BT24: 0 | BU24: 0 | BV24: 0 | BW24: 0 | BX24: 0 | BY24: 0 | BZ24: 0 | CA24: 0 | CB24: 0 | CC24: 0 | CD24: 0 | CE24: 0 | CF24: 0 | CG24: 0 | CH24: 0 | CI24: 0 | CJ24: 0 | CK24: 0 | CL24: 0 | CM24: 0 | CN24: 0 | CO24: 0 | CP24: 0 | CQ24: 0 | CR24: 0 | CS24: 0 | CT24: 0 | CU24: 0 | CV24: 0 | CW24: 0 | CX24: 0
A25: Capacity-based | B25: {='Inputs and Outputs'!B130:CX130} -> 0 | C25: 0 | D25: 0 | E25: 0 | F25: 0 | G25: 0 | H25: 0 | I25: 0 | J25: 0 | K25: 0 | L25: 0 | M25: 0 | N25: 0 | O25: 0 | P25: 0 | Q25: 0 | R25: 0 | S25: 0 | T25: 0 | U25: 0 | V25: 0 | W25: 0 | X25: 0 | Y25: 0 | Z25: 0 | AA25: 0 | AB25: 0 | AC25: 0 | AD25: 0 | AE25: 0 | AF25: 0 | AG25: 0 | AH25: 0 | AI25: 0 | AJ25: 0 | AK25: 0 | AL25: 0 | AM25: 0 | AN25: 0 | AO25: 0 | AP25: 0 | AQ25: 0 | AR25: 0 | AS25: 0 | AT25: 0 | AU25: 0 | AV25: 0 | AW25: 0 | AX25: 0 | AY25: 0 | AZ25: 0 | BA25: 0 | BB25: 0 | BC25: 0 | BD25: 0 | BE25: 0 | BF25: 0 | BG25: 0 | BH25: 0 | BI25: 0 | BJ25: 0 | BK25: 0 | BL25: 0 | BM25: 0 | BN25: 0 | BO25: 0 | BP25: 0 | BQ25: 0 | BR25: 0 | BS25: 0 | BT25: 0 | BU25: 0 | BV25: 0 | BW25: 0 | BX25: 0 | BY25: 0 | BZ25: 0 | CA25: 0 | CB25: 0 | CC25: 0 | CD25: 0 | CE25: 0 | CF25: 0 | CG25: 0 | CH25: 0 | CI25: 0 | CJ25: 0 | CK25: 0 | CL25: 0 | CM25: 0 | CN25: 0 | CO25: 0 | CP25: 0 | CQ25: 0 | CR25: 0 | CS25: 0 | CT25: 0 | CU25: 0 | CV25: 0 | CW25: 0 | CX25: 0
A26: Variable | B26: {='Inputs and Outputs'!B131:CX131} -> 0 | C26: 0 | D26: 0 | E26: 0 | F26: 0 | G26: 0 | H26: 0 | I26: 0 | J26: 0 | K26: 0 | L26: 0 | M26: 0 | N26: 0 | O26: 0 | P26: 0 | Q26: 0 | R26: 0 | S26: 0 | T26: 0 | U26: 0 | V26: 0 | W26: 0 | X26: 0 | Y26: 0 | Z26: 0 | AA26: 0 | AB26: 0 | AC26: 0 | AD26: 0 | AE26: 0 | AF26: 0 | AG26: 0 | AH26: 0 | AI26: 0 | AJ26: 0 | AK26: 0 | AL26: 0 | AM26: 0 | AN26: 0 | AO26: 0 | AP26: 0 | AQ26: 0 | AR26: 0 | AS26: 0 | AT26: 0 | AU26: 0 | AV26: 0 | AW26: 0 | AX26: 0 | AY26: 0 | AZ26: 0 | BA26: 0 | BB26: 0 | BC26: 0 | BD26: 0 | BE26: 0 | BF26: 0 | BG26: 0 | BH26: 0 | BI26: 0 | BJ26: 0 | BK26: 0 | BL26: 0 | BM26: 0 | BN26: 0 | BO26: 0 | BP26: 0 | BQ26: 0 | BR26: 0 | BS26: 0 | BT26: 0 | BU26: 0 | BV26: 0 | BW26: 0 | BX26: 0 | BY26: 0 | BZ26: 0 | CA26: 0 | CB26: 0 | CC26: 0 | CD26: 0 | CE26: 0 | CF26: 0 | CG26: 0 | CH26: 0 | CI26: 0 | CJ26: 0 | CK26: 0 | CL26: 0 | CM26: 0 | CN26: 0 | CO26: 0 | CP26: 0 | CQ26: 0 | CR26: 0 | CS26: 0 | CT26: 0 | CU26: 0 | CV26: 0 | CW26: 0 | CX26: 0
A27: Fuel cell operating costs
A28: Fixed | B28: {='Inputs and Outputs'!B133:CX133} -> 0 | C28: 0 | D28: 0 | E28: 0 | F28: 0 | G28: 0 | H28: 0 | I28: 0 | J28: 0 | K28: 0 | L28: 0 | M28: 0 | N28: 0 | O28: 0 | P28: 0 | Q28: 0 | R28: 0 | S28: 0 | T28: 0 | U28: 0 | V28: 0 | W28: 0 | X28: 0 | Y28: 0 | Z28: 0 | AA28: 0 | AB28: 0 | AC28: 0 | AD28: 0 | AE28: 0 | AF28: 0 | AG28: 0 | AH28: 0 | AI28: 0 | AJ28: 0 | AK28: 0 | AL28: 0 | AM28: 0 | AN28: 0 | AO28: 0 | AP28: 0 | AQ28: 0 | AR28: 0 | AS28: 0 | AT28: 0 | AU28: 0 | AV28: 0 | AW28: 0 | AX28: 0 | AY28: 0 | AZ28: 0 | BA28: 0 | BB28: 0 | BC28: 0 | BD28: 0 | BE28: 0 | BF28: 0 | BG28: 0 | BH28: 0 | BI28: 0 | BJ28: 0 | BK28: 0 | BL28: 0 | BM28: 0 | BN28: 0 | BO28: 0 | BP28: 0 | BQ28: 0 | BR28: 0 | BS28: 0 | BT28: 0 | BU28: 0 | BV28: 0 | BW28: 0 | BX28: 0 | BY28: 0 | BZ28: 0 | CA28: 0 | CB28: 0 | CC28: 0 | CD28: 0 | CE28: 0 | CF28: 0 | CG28: 0 | CH28: 0 | CI28: 0 | CJ28: 0 | CK28: 0 | CL28: 0 | CM28: 0 | CN28: 0 | CO28: 0 | CP28: 0 | CQ28: 0 | CR28: 0 | CS28: 0 | CT28: 0 | CU28: 0 | CV28: 0 | CW28: 0 | CX28: 0
A29: Capacity-based | B29: {='Inputs and Outputs'!B134:CX134} -> 0 | C29: 0 | D29: 0 | E29: 0 | F29: 0 | G29: 0 | H29: 0 | I29: 0 | J29: 0 | K29: 0 | L29: 0 | M29: 0 | N29: 0 | O29: 0 | P29: 0 | Q29: 0 | R29: 0 | S29: 0 | T29: 0 | U29: 0 | V29: 0 | W29: 0 | X29: 0 | Y29: 0 | Z29: 0 | AA29: 0 | AB29: 0 | AC29: 0 | AD29: 0 | AE29: 0 | AF29: 0 | AG29: 0 | AH29: 0 | AI29: 0 | AJ29: 0 | AK29: 0 | AL29: 0 | AM29: 0 | AN29: 0 | AO29: 0 | AP29: 0 | AQ29: 0 | AR29: 0 | AS29: 0 | AT29: 0 | AU29: 0 | AV29: 0 | AW29: 0 | AX29: 0 | AY29: 0 | AZ29: 0 | BA29: 0 | BB29: 0 | BC29: 0 | BD29: 0 | BE29: 0 | BF29: 0 | BG29: 0 | BH29: 0 | BI29: 0 | BJ29: 0 | BK29: 0 | BL29: 0 | BM29: 0 | BN29: 0 | BO29: 0 | BP29: 0 | BQ29: 0 | BR29: 0 | BS29: 0 | BT29: 0 | BU29: 0 | BV29: 0 | BW29: 0 | BX29: 0 | BY29: 0 | BZ29: 0 | CA29: 0 | CB29: 0 | CC29: 0 | CD29: 0 | CE29: 0 | CF29: 0 | CG29: 0 | CH29: 0 | CI29: 0 | CJ29: 0 | CK29: 0 | CL29: 0 | CM29: 0 | CN29: 0 | CO29: 0 | CP29: 0 | CQ29: 0 | CR29: 0 | CS29: 0 | CT29: 0 | CU29: 0 | CV29: 0 | CW29: 0 | CX29: 0
A30: Variable | B30: {='Inputs and Outputs'!B135:CX135} -> 0 | C30: 0 | D30: 0 | E30: 0 | F30: 0 | G30: 0 | H30: 0 | I30: 0 | J30: 0 | K30: 0 | L30: 0 | M30: 0 | N30: 0 | O30: 0 | P30: 0 | Q30: 0 | R30: 0 | S30: 0 | T30: 0 | U30: 0 | V30: 0 | W30: 0 | X30: 0 | Y30: 0 | Z30: 0 | AA30: 0 | AB30: 0 | AC30: 0 | AD30: 0 | AE30: 0 | AF30: 0 | AG30: 0 | AH30: 0 | AI30: 0 | AJ30: 0 | AK30: 0 | AL30: 0 | AM30: 0 | AN30: 0 | AO30: 0 | AP30: 0 | AQ30: 0 | AR30: 0 | AS30: 0 | AT30: 0 | AU30: 0 | AV30: 0 | AW30: 0 | AX30: 0 | AY30: 0 | AZ30: 0 | BA30: 0 | BB30: 0 | BC30: 0 | BD30: 0 | BE30: 0 | BF30: 0 | BG30: 0 | BH30: 0 | BI30: 0 | BJ30: 0 | BK30: 0 | BL30: 0 | BM30: 0 | BN30: 0 | BO30: 0 | BP30: 0 | BQ30: 0 | BR30: 0 | BS30: 0 | BT30: 0 | BU30: 0 | BV30: 0 | BW30: 0 | BX30: 0 | BY30: 0 | BZ30: 0 | CA30: 0 | CB30: 0 | CC30: 0 | CD30: 0 | CE30: 0 | CF30: 0 | CG30: 0 | CH30: 0 | CI30: 0 | CJ30: 0 | CK30: 0 | CL30: 0 | CM30: 0 | CN30: 0 | CO30: 0 | CP30: 0 | CQ30: 0 | CR30: 0 | CS30: 0 | CT30: 0 | CU30: 0 | CV30: 0 | CW30: 0 | CX30: 0
A31: Replacement | B31: {='Inputs and Outputs'!B136:CX136} -> 0 | C31: 0 | D31: 0 | E31: 0 | F31: 0 | G31: 0 | H31: 0 | I31: 0 | J31: 0 | K31: 0 | L31: 0 | M31: 0 | N31: 0 | O31: 0 | P31: 0 | Q31: 0 | R31: 0 | S31: 0 | T31: 0 | U31: 0 | V31: 0 | W31: 0 | X31: 0 | Y31: 0 | Z31: 0 | AA31: 0 | AB31: 0 | AC31: 0 | AD31: 0 | AE31: 0 | AF31: 0 | AG31: 0 | AH31: 0 | AI31: 0 | AJ31: 0 | AK31: 0 | AL31: 0 | AM31: 0 | AN31: 0 | AO31: 0 | AP31: 0 | AQ31: 0 | AR31: 0 | AS31: 0 | AT31: 0 | AU31: 0 | AV31: 0 | AW31: 0 | AX31: 0 | AY31: 0 | AZ31: 0 | BA31: 0 | BB31: 0 | BC31: 0 | BD31: 0 | BE31: 0 | BF31: 0 | BG31: 0 | BH31: 0 | BI31: 0 | BJ31: 0 | BK31: 0 | BL31: 0 | BM31: 0 | BN31: 0 | BO31: 0 | BP31: 0 | BQ31: 0 | BR31: 0 | BS31: 0 | BT31: 0 | BU31: 0 | BV31: 0 | BW31: 0 | BX31: 0 | BY31: 0 | BZ31: 0 | CA31: 0 | CB31: 0 | CC31: 0 | CD31: 0 | CE31: 0 | CF31: 0 | CG31: 0 | CH31: 0 | CI31: 0 | CJ31: 0 | CK31: 0 | CL31: 0 | CM31: 0 | CN31: 0 | CO31: 0 | CP31: 0 | CQ31: 0 | CR31: 0 | CS31: 0 | CT31: 0 | CU31: 0 | CV31: 0 | CW31: 0 | CX31: 0
A32: Fuel | B32: {='Inputs and Outputs'!B137:CX137} -> 0 | C32: 0 | D32: 0 | E32: 0 | F32: 0 | G32: 0 | H32: 0 | I32: 0 | J32: 0 | K32: 0 | L32: 0 | M32: 0 | N32: 0 | O32: 0 | P32: 0 | Q32: 0 | R32: 0 | S32: 0 | T32: 0 | U32: 0 | V32: 0 | W32: 0 | X32: 0 | Y32: 0 | Z32: 0 | AA32: 0 | AB32: 0 | AC32: 0 | AD32: 0 | AE32: 0 | AF32: 0 | AG32: 0 | AH32: 0 | AI32: 0 | AJ32: 0 | AK32: 0 | AL32: 0 | AM32: 0 | AN32: 0 | AO32: 0 | AP32: 0 | AQ32: 0 | AR32: 0 | AS32: 0 | AT32: 0 | AU32: 0 | AV32: 0 | AW32: 0 | AX32: 0 | AY32: 0 | AZ32: 0 | BA32: 0 | BB32: 0 | BC32: 0 | BD32: 0 | BE32: 0 | BF32: 0 | BG32: 0 | BH32: 0 | BI32: 0 | BJ32: 0 | BK32: 0 | BL32: 0 | BM32: 0 | BN32: 0 | BO32: 0 | BP32: 0 | BQ32: 0 | BR32: 0 | BS32: 0 | BT32: 0 | BU32: 0 | BV32: 0 | BW32: 0 | BX32: 0 | BY32: 0 | BZ32: 0 | CA32: 0 | CB32: 0 | CC32: 0 | CD32: 0 | CE32: 0 | CF32: 0 | CG32: 0 | CH32: 0 | CI32: 0 | CJ32: 0 | CK32: 0 | CL32: 0 | CM32: 0 | CN32: 0 | CO32: 0 | CP32: 0 | CQ32: 0 | CR32: 0 | CS32: 0 | CT32: 0 | CU32: 0 | CV32: 0 | CW32: 0 | CX32: 0
A33: Fuel
A34: Fuel cost, CSP and generic system only | C34: =IF(ISNUMBER(outYear),om_fuel_cost*system_heat_rate*(annual_fuel_usage/1000)*(1+inflation_rate/100+om_fuel_cost_escal/100)^B2,"") | D34: =IF(ISNUMBER(outYear),om_fuel_cost*system_heat_rate*(annual_fuel_usage/1000)*(1+inflation_rate/100+om_fuel_cost_escal/100)^C2,"") | E34: =IF(ISNUMBER(outYear),om_fuel_cost*system_heat_rate*(annual_fuel_usage/1000)*(1+inflation_rate/100+om_fuel_cost_escal/100)^D2,"") | F34: =IF(ISNUMBER(outYear),om_fuel_cost*system_heat_rate*(annual_fuel_usage/1000)*(1+inflation_rate/100+om_fuel_cost_escal/100)^E2,"") | G34: =IF(ISNUMBER(outYear),om_fuel_cost*system_heat_rate*(annual_fuel_usage/1000)*(1+inflation_rate/100+om_fuel_cost_escal/100)^F2,"") | H34: =IF(ISNUMBER(outYear),om_fuel_cost*system_heat_rate*(annual_fuel_usage/1000)*(1+inflation_rate/100+om_fuel_cost_escal/100)^G2,"") | I34: =IF(ISNUMBER(outYear),om_fuel_cost*system_heat_rate*(annual_fuel_usage/1000)*(1+inflation_rate/100+om_fuel_cost_escal/100)^H2,"") | J34: =IF(ISNUMBER(outYear),om_fuel_cost*system_heat_rate*(annual_fuel_usage/1000)*(1+inflation_rate/100+om_fuel_cost_escal/100)^I2,"") | ... CX34: =IF(ISNUMBER(outYear),om_fuel_cost*system_heat_rate*(annual_fuel_usage/1000)*(1+inflation_rate/100+om_fuel_cost_escal/100)^CW2,"")
A35: Or from annual schedule | C35: 0 | D35: 0 | E35: 0 | F35: 0 | G35: 0 | H35: 0 | I35: 0 | J35: 0 | K35: 0 | L35: 0 | M35: 0 | N35: 0 | O35: 0 | P35: 0 | Q35: 0 | R35: 0 | S35: 0 | T35: 0 | U35: 0 | V35: 0 | W35: 0 | X35: 0 | Y35: 0 | Z35: 0 | AA35: 0 | AB35: 0 | AC35: 0 | AD35: 0 | AE35: 0 | AF35: 0
A36: Biomass feedstock, biopower only | C36: =IF(ISNUMBER(outYear),om_opt_fuel_1_cost*om_opt_fuel_1_usage*(1+inflation_rate/100+om_opt_fuel_1_cost_escal/100)^B2,"") | D36: =IF(ISNUMBER(outYear),om_opt_fuel_1_cost*om_opt_fuel_1_usage*(1+inflation_rate/100+om_opt_fuel_1_cost_escal/100)^C2,"") | E36: =IF(ISNUMBER(outYear),om_opt_fuel_1_cost*om_opt_fuel_1_usage*(1+inflation_rate/100+om_opt_fuel_1_cost_escal/100)^D2,"") | F36: =IF(ISNUMBER(outYear),om_opt_fuel_1_cost*om_opt_fuel_1_usage*(1+inflation_rate/100+om_opt_fuel_1_cost_escal/100)^E2,"") | G36: =IF(ISNUMBER(outYear),om_opt_fuel_1_cost*om_opt_fuel_1_usage*(1+inflation_rate/100+om_opt_fuel_1_cost_escal/100)^F2,"") | H36: =IF(ISNUMBER(outYear),om_opt_fuel_1_cost*om_opt_fuel_1_usage*(1+inflation_rate/100+om_opt_fuel_1_cost_escal/100)^G2,"") | I36: =IF(ISNUMBER(outYear),om_opt_fuel_1_cost*om_opt_fuel_1_usage*(1+inflation_rate/100+om_opt_fuel_1_cost_escal/100)^H2,"") | J36: =IF(ISNUMBER(outYear),om_opt_fuel_1_cost*om_opt_fuel_1_usage*(1+inflation_rate/100+om_opt_fuel_1_cost_escal/100)^I2,"") | ... CX36: =IF(ISNUMBER(outYear),om_opt_fuel_1_cost*om_opt_fuel_1_usage*(1+inflation_rate/100+om_opt_fuel_1_cost_escal/100)^CW2,"")
A37: Coal feedstock, biopower only | C37: =IF(ISNUMBER(outYear),om_opt_fuel_2_cost*om_opt_fuel_2_usage*(1+inflation_rate/100+om_opt_fuel_2_cost_escal/100)^B2,"") | D37: =IF(ISNUMBER(outYear),om_opt_fuel_2_cost*om_opt_fuel_2_usage*(1+inflation_rate/100+om_opt_fuel_2_cost_escal/100)^C2,"") | E37: =IF(ISNUMBER(outYear),om_opt_fuel_2_cost*om_opt_fuel_2_usage*(1+inflation_rate/100+om_opt_fuel_2_cost_escal/100)^D2,"") | F37: =IF(ISNUMBER(outYear),om_opt_fuel_2_cost*om_opt_fuel_2_usage*(1+inflation_rate/100+om_opt_fuel_2_cost_escal/100)^E2,"") | G37: =IF(ISNUMBER(outYear),om_opt_fuel_2_cost*om_opt_fuel_2_usage*(1+inflation_rate/100+om_opt_fuel_2_cost_escal/100)^F2,"") | H37: =IF(ISNUMBER(outYear),om_opt_fuel_2_cost*om_opt_fuel_2_usage*(1+inflation_rate/100+om_opt_fuel_2_cost_escal/100)^G2,"") | I37: =IF(ISNUMBER(outYear),om_opt_fuel_2_cost*om_opt_fuel_2_usage*(1+inflation_rate/100+om_opt_fuel_2_cost_escal/100)^H2,"") | J37: =IF(ISNUMBER(outYear),om_opt_fuel_2_cost*om_opt_fuel_2_usage*(1+inflation_rate/100+om_opt_fuel_2_cost_escal/100)^I2,"") | ... CX37: =IF(ISNUMBER(outYear),om_opt_fuel_2_cost*om_opt_fuel_2_usage*(1+inflation_rate/100+om_opt_fuel_2_cost_escal/100)^CW2,"")
A38: Insurance | C38: =IF(ISNUMBER(outYear),total_installed_cost*insurance_rate/100*(1+inflation_rate/100)^B2,"") | D38: =IF(ISNUMBER(outYear),total_installed_cost*insurance_rate/100*(1+inflation_rate/100)^C2,"") | E38: =IF(ISNUMBER(outYear),total_installed_cost*insurance_rate/100*(1+inflation_rate/100)^D2,"") | F38: =IF(ISNUMBER(outYear),total_installed_cost*insurance_rate/100*(1+inflation_rate/100)^E2,"") | G38: =IF(ISNUMBER(outYear),total_installed_cost*insurance_rate/100*(1+inflation_rate/100)^F2,"") | H38: =IF(ISNUMBER(outYear),total_installed_cost*insurance_rate/100*(1+inflation_rate/100)^G2,"") | I38: =IF(ISNUMBER(outYear),total_installed_cost*insurance_rate/100*(1+inflation_rate/100)^H2,"") | J38: =IF(ISNUMBER(outYear),total_installed_cost*insurance_rate/100*(1+inflation_rate/100)^I2,"") | ... CX38: =IF(ISNUMBER(outYear),total_installed_cost*insurance_rate/100*(1+inflation_rate/100)^CW2,"")
A39: Property tax | C39: =IF(ISNUMBER(outYear),C43*property_tax_rate/100,"") | D39: =IF(ISNUMBER(outYear),D43*property_tax_rate/100,"") | E39: =IF(ISNUMBER(outYear),E43*property_tax_rate/100,"") | F39: =IF(ISNUMBER(outYear),F43*property_tax_rate/100,"") | G39: =IF(ISNUMBER(outYear),G43*property_tax_rate/100,"") | H39: =IF(ISNUMBER(outYear),H43*property_tax_rate/100,"") | I39: =IF(ISNUMBER(outYear),I43*property_tax_rate/100,"") | J39: =IF(ISNUMBER(outYear),J43*property_tax_rate/100,"") | ... CX39: =IF(ISNUMBER(outYear),CX43*property_tax_rate/100,"")
A40: Salvage value | C40: =IF(ISNUMBER(outYear),IF((outYear=analysis_period),total_installed_cost*salvage_percentage/100,0),"") | D40: =IF(ISNUMBER(outYear),IF((outYear=analysis_period),total_installed_cost*salvage_percentage/100,0),"") | E40: =IF(ISNUMBER(outYear),IF((outYear=analysis_period),total_installed_cost*salvage_percentage/100,0),"") | F40: =IF(ISNUMBER(outYear),IF((outYear=analysis_period),total_installed_cost*salvage_percentage/100,0),"") | G40: =IF(ISNUMBER(outYear),IF((outYear=analysis_period),total_installed_cost*salvage_percentage/100,0),"") | H40: =IF(ISNUMBER(outYear),IF((outYear=analysis_period),total_installed_cost*salvage_percentage/100,0),"") | I40: =IF(ISNUMBER(outYear),IF((outYear=analysis_period),total_installed_cost*salvage_percentage/100,0),"") | J40: =IF(ISNUMBER(outYear),IF((outYear=analysis_period),total_installed_cost*salvage_percentage/100,0),"") | ... CX40: =IF(ISNUMBER(outYear),IF((outYear=analysis_period),total_installed_cost*salvage_percentage/100,0),"")
A41: Total operating expenses | C41: =IF(ISNUMBER(outYear),SUM(C16:C39)-C40,"") | D41: =IF(ISNUMBER(outYear),SUM(D16:D39)-D40,"") | E41: =IF(ISNUMBER(outYear),SUM(E16:E39)-E40,"") | F41: =IF(ISNUMBER(outYear),SUM(F16:F39)-F40,"") | G41: =IF(ISNUMBER(outYear),SUM(G16:G39)-G40,"") | H41: =IF(ISNUMBER(outYear),SUM(H16:H39)-H40,"") | I41: =IF(ISNUMBER(outYear),SUM(I16:I39)-I40,"") | J41: =IF(ISNUMBER(outYear),SUM(J16:J39)-J40,"") | ... CX41: =IF(ISNUMBER(outYear),SUM(CX16:CX39)-CX40,"")
A43: Property assesed value | C43: =IF(ISNUMBER(outYear),IF( (1-(outYear-1)*prop_tax_assessed_decline/100)>0,(1-(outYear-1)*prop_tax_assessed_decline/100)*total_installed_cost*prop_tax_cost_assessed_percent/100,0 ),"") | D43: =IF(ISNUMBER(outYear),IF( (1-(outYear-1)*prop_tax_assessed_decline/100)>0,(1-(outYear-1)*prop_tax_assessed_decline/100)*total_installed_cost*prop_tax_cost_assessed_percent/100,0 ),"") | E43: =IF(ISNUMBER(outYear),IF( (1-(outYear-1)*prop_tax_assessed_decline/100)>0,(1-(outYear-1)*prop_tax_assessed_decline/100)*total_installed_cost*prop_tax_cost_assessed_percent/100,0 ),"") | F43: =IF(ISNUMBER(outYear),IF( (1-(outYear-1)*prop_tax_assessed_decline/100)>0,(1-(outYear-1)*prop_tax_assessed_decline/100)*total_installed_cost*prop_tax_cost_assessed_percent/100,0 ),"") | G43: =IF(ISNUMBER(outYear),IF( (1-(outYear-1)*prop_tax_assessed_decline/100)>0,(1-(outYear-1)*prop_tax_assessed_decline/100)*total_installed_cost*prop_tax_cost_assessed_percent/100,0 ),"") | H43: =IF(ISNUMBER(outYear),IF( (1-(outYear-1)*prop_tax_assessed_decline/100)>0,(1-(outYear-1)*prop_tax_assessed_decline/100)*total_installed_cost*prop_tax_cost_assessed_percent/100,0 ),"") | I43: =IF(ISNUMBER(outYear),IF( (1-(outYear-1)*prop_tax_assessed_decline/100)>0,(1-(outYear-1)*prop_tax_assessed_decline/100)*total_installed_cost*prop_tax_cost_assessed_percent/100,0 ),"") | J43: =IF(ISNUMBER(outYear),IF( (1-(outYear-1)*prop_tax_assessed_decline/100)>0,(1-(outYear-1)*prop_tax_assessed_decline/100)*total_installed_cost*prop_tax_cost_assessed_percent/100,0 ),"") | ... CX43: =IF(ISNUMBER(outYear),IF( (1-(outYear-1)*prop_tax_assessed_decline/100)>0,(1-(outYear-1)*prop_tax_assessed_decline/100)*total_installed_cost*prop_tax_cost_assessed_percent/100,0 ),"")
A45: Tax Deductible Operating Expenses
...

Sheet Depreciation Schedules
A1: Depreciation Schedules (Half Year)
A2: Year | B2: 5-yr MACRS | C2: 15-yr MACRS | D2: 5-yr SL | E2: 15-yr SL | F2: 20-yr SL | G2: 39-yr SL
A3: 1 | B3: 20 | C3: 5 | D3: 10 | E3: 3.33 | F3: 2.5 | G3: =2.56410256410256*0.5 -> 1.2820513
A4: 2 | B4: 32 | C4: 9.5 | D4: 20 | E4: 6.67 | F4: 5 | G4: 2.5641026
A5: 3 | B5: 19.2 | C5: 8.55 | D5: 20 | E5: 6.67 | F5: 5 | G5: 2.5641026
A6: 4 | B6: 11.52 | C6: 7.7 | D6: 20 | E6: 6.67 | F6: 5 | G6: 2.5641026
A7: 5 | B7: 11.52 | C7: 6.93 | D7: 20 | E7: 6.67 | F7: 5 | G7: 2.5641026
A8: 6 | B8: 5.76 | C8: 6.23 | D8: 10 | E8: 6.67 | F8: 5 | G8: 2.5641026
A9: 7 | B9: 0 | C9: 5.9 | D9: 0 | E9: 6.67 | F9: 5 | G9: 2.5641026
A10: 8 | B10: 0 | C10: 5.9 | D10: 0 | E10: 6.67 | F10: 5 | G10: 2.5641026
A11: 9 | B11: 0 | C11: 5.91 | D11: 0 | E11: 6.67 | F11: 5 | G11: 2.5641026
A12: 10 | B12: 0 | C12: 5.9 | D12: 0 | E12: 6.67 | F12: 5 | G12: 2.5641026
A13: 11 | B13: 0 | C13: 5.91 | D13: 0 | E13: 6.67 | F13: 5 | G13: 2.5641026
A14: 12 | B14: 0 | C14: 5.9 | D14: 0 | E14: 6.66 | F14: 5 | G14: 2.5641026
A15: 13 | B15: 0 | C15: 5.91 | D15: 0 | E15: 6.67 | F15: 5 | G15: 2.5641026
... A41: 39 | B41: 0 | C41: 0 | D41: 0 | E41: 0 | F41: 0 | G41: 2.5641026
A42: 40 | B42: 0 | C42: 0 | D42: 0 | E42: 0 | F42: 0 | G42: =2.56410256410256*0.5 -> 1.2820513
A43: For additional information on depreciation schedules, see IRS publication 946.
A44: http://www.irs.gov/pub/irs-pdf/p946.pdf
A45: * Note custom schedule is defined on Inputs sheet around Row 180
